2024-11-21 16:06:45,873 [DEBUG] DroneApp has started! Directory ./
2024-11-21 16:06:47,402 [INFO] ArduCopter V4.6.0-dev (3764f377)
2024-11-21 16:06:47,403 [INFO] 08849941057b4f329db74127f3309984
2024-11-21 16:06:47,404 [INFO] Frame: QUAD/PLUS
2024-11-21 16:06:48,295 [INFO] Connected to Simulator On Port: 14553 
2024-11-21 16:06:48,296 [INFO] Engine started
2024-11-21 16:06:48,296 [INFO] Drone connected
2024-11-21 16:06:53,376 [ERROR] ConnectionWatchdog - Network is unreachable: 
Traceback (most recent call last):
  File "/usr/lib/python3.9/urllib/request.py", line 1346, in do_open
    h.request(req.get_method(), req.selector, req.data, headers,
  File "/usr/lib/python3.9/http/client.py", line 1255, in request
    self._send_request(method, url, body, headers, encode_chunked)
  File "/usr/lib/python3.9/http/client.py", line 1301, in _send_request
    self.endheaders(body, encode_chunked=encode_chunked)
  File "/usr/lib/python3.9/http/client.py", line 1250, in endheaders
    self._send_output(message_body, encode_chunked=encode_chunked)
  File "/usr/lib/python3.9/http/client.py", line 1010, in _send_output
    self.send(msg)
  File "/usr/lib/python3.9/http/client.py", line 950, in send
    self.connect()
  File "/usr/lib/python3.9/http/client.py", line 921, in connect
    self.sock = self._create_connection(
  File "/usr/lib/python3.9/socket.py", line 843, in create_connection
    raise err
  File "/usr/lib/python3.9/socket.py", line 831, in create_connection
    sock.connect(sa)
ConnectionRefusedError: [Errno 111] Connection refused

During handling of the above exception, another exception occurred:

Traceback (most recent call last):
  File "/home/gourav/raspi-app/connection_watchdog.py", line 40, in is_internet_on
    urlopen(str('http://' + self.host_ip), timeout=5)
  File "/usr/lib/python3.9/urllib/request.py", line 214, in urlopen
    return opener.open(url, data, timeout)
  File "/usr/lib/python3.9/urllib/request.py", line 517, in open
    response = self._open(req, data)
  File "/usr/lib/python3.9/urllib/request.py", line 534, in _open
    result = self._call_chain(self.handle_open, protocol, protocol +
  File "/usr/lib/python3.9/urllib/request.py", line 494, in _call_chain
    result = func(*args)
  File "/usr/lib/python3.9/urllib/request.py", line 1375, in http_open
    return self.do_open(http.client.HTTPConnection, req)
  File "/usr/lib/python3.9/urllib/request.py", line 1349, in do_open
    raise URLError(err)
urllib.error.URLError: <urlopen error [Errno 111] Connection refused>
2024-11-21 16:06:53,389 [INFO] Freezing in a spot
2024-11-21 16:06:53,391 [INFO] Connection attempt 1, max_reconnection_attempts 180
2024-11-21 16:06:54,467 [ERROR] ConnectionWatchdog - Network is unreachable: 
Traceback (most recent call last):
  File "/usr/lib/python3.9/urllib/request.py", line 1346, in do_open
    h.request(req.get_method(), req.selector, req.data, headers,
  File "/usr/lib/python3.9/http/client.py", line 1255, in request
    self._send_request(method, url, body, headers, encode_chunked)
  File "/usr/lib/python3.9/http/client.py", line 1301, in _send_request
    self.endheaders(body, encode_chunked=encode_chunked)
  File "/usr/lib/python3.9/http/client.py", line 1250, in endheaders
    self._send_output(message_body, encode_chunked=encode_chunked)
  File "/usr/lib/python3.9/http/client.py", line 1010, in _send_output
    self.send(msg)
  File "/usr/lib/python3.9/http/client.py", line 950, in send
    self.connect()
  File "/usr/lib/python3.9/http/client.py", line 921, in connect
    self.sock = self._create_connection(
  File "/usr/lib/python3.9/socket.py", line 843, in create_connection
    raise err
  File "/usr/lib/python3.9/socket.py", line 831, in create_connection
    sock.connect(sa)
ConnectionRefusedError: [Errno 111] Connection refused

During handling of the above exception, another exception occurred:

Traceback (most recent call last):
  File "/home/gourav/raspi-app/connection_watchdog.py", line 40, in is_internet_on
    urlopen(str('http://' + self.host_ip), timeout=5)
  File "/usr/lib/python3.9/urllib/request.py", line 214, in urlopen
    return opener.open(url, data, timeout)
  File "/usr/lib/python3.9/urllib/request.py", line 517, in open
    response = self._open(req, data)
  File "/usr/lib/python3.9/urllib/request.py", line 534, in _open
    result = self._call_chain(self.handle_open, protocol, protocol +
  File "/usr/lib/python3.9/urllib/request.py", line 494, in _call_chain
    result = func(*args)
  File "/usr/lib/python3.9/urllib/request.py", line 1375, in http_open
    return self.do_open(http.client.HTTPConnection, req)
  File "/usr/lib/python3.9/urllib/request.py", line 1349, in do_open
    raise URLError(err)
urllib.error.URLError: <urlopen error [Errno 111] Connection refused>
2024-11-21 16:06:54,470 [INFO] Freezing in a spot
2024-11-21 16:06:54,471 [INFO] Connection attempt 2, max_reconnection_attempts 180
2024-11-21 16:06:55,611 [ERROR] ConnectionWatchdog - Network is unreachable: 
Traceback (most recent call last):
  File "/usr/lib/python3.9/urllib/request.py", line 1346, in do_open
    h.request(req.get_method(), req.selector, req.data, headers,
  File "/usr/lib/python3.9/http/client.py", line 1255, in request
    self._send_request(method, url, body, headers, encode_chunked)
  File "/usr/lib/python3.9/http/client.py", line 1301, in _send_request
    self.endheaders(body, encode_chunked=encode_chunked)
  File "/usr/lib/python3.9/http/client.py", line 1250, in endheaders
    self._send_output(message_body, encode_chunked=encode_chunked)
  File "/usr/lib/python3.9/http/client.py", line 1010, in _send_output
    self.send(msg)
  File "/usr/lib/python3.9/http/client.py", line 950, in send
    self.connect()
  File "/usr/lib/python3.9/http/client.py", line 921, in connect
    self.sock = self._create_connection(
  File "/usr/lib/python3.9/socket.py", line 843, in create_connection
    raise err
  File "/usr/lib/python3.9/socket.py", line 831, in create_connection
    sock.connect(sa)
ConnectionRefusedError: [Errno 111] Connection refused

During handling of the above exception, another exception occurred:

Traceback (most recent call last):
  File "/home/gourav/raspi-app/connection_watchdog.py", line 40, in is_internet_on
    urlopen(str('http://' + self.host_ip), timeout=5)
  File "/usr/lib/python3.9/urllib/request.py", line 214, in urlopen
    return opener.open(url, data, timeout)
  File "/usr/lib/python3.9/urllib/request.py", line 517, in open
    response = self._open(req, data)
  File "/usr/lib/python3.9/urllib/request.py", line 534, in _open
    result = self._call_chain(self.handle_open, protocol, protocol +
  File "/usr/lib/python3.9/urllib/request.py", line 494, in _call_chain
    result = func(*args)
  File "/usr/lib/python3.9/urllib/request.py", line 1375, in http_open
    return self.do_open(http.client.HTTPConnection, req)
  File "/usr/lib/python3.9/urllib/request.py", line 1349, in do_open
    raise URLError(err)
urllib.error.URLError: <urlopen error [Errno 111] Connection refused>
2024-11-21 16:06:55,614 [INFO] Freezing in a spot
2024-11-21 16:06:55,616 [INFO] Connection attempt 3, max_reconnection_attempts 180
2024-11-21 16:06:56,737 [ERROR] ConnectionWatchdog - Network is unreachable: 
Traceback (most recent call last):
  File "/usr/lib/python3.9/urllib/request.py", line 1346, in do_open
    h.request(req.get_method(), req.selector, req.data, headers,
  File "/usr/lib/python3.9/http/client.py", line 1255, in request
    self._send_request(method, url, body, headers, encode_chunked)
  File "/usr/lib/python3.9/http/client.py", line 1301, in _send_request
    self.endheaders(body, encode_chunked=encode_chunked)
  File "/usr/lib/python3.9/http/client.py", line 1250, in endheaders
    self._send_output(message_body, encode_chunked=encode_chunked)
  File "/usr/lib/python3.9/http/client.py", line 1010, in _send_output
    self.send(msg)
  File "/usr/lib/python3.9/http/client.py", line 950, in send
    self.connect()
  File "/usr/lib/python3.9/http/client.py", line 921, in connect
    self.sock = self._create_connection(
  File "/usr/lib/python3.9/socket.py", line 843, in create_connection
    raise err
  File "/usr/lib/python3.9/socket.py", line 831, in create_connection
    sock.connect(sa)
ConnectionRefusedError: [Errno 111] Connection refused

During handling of the above exception, another exception occurred:

Traceback (most recent call last):
  File "/home/gourav/raspi-app/connection_watchdog.py", line 40, in is_internet_on
    urlopen(str('http://' + self.host_ip), timeout=5)
  File "/usr/lib/python3.9/urllib/request.py", line 214, in urlopen
    return opener.open(url, data, timeout)
  File "/usr/lib/python3.9/urllib/request.py", line 517, in open
    response = self._open(req, data)
  File "/usr/lib/python3.9/urllib/request.py", line 534, in _open
    result = self._call_chain(self.handle_open, protocol, protocol +
  File "/usr/lib/python3.9/urllib/request.py", line 494, in _call_chain
    result = func(*args)
  File "/usr/lib/python3.9/urllib/request.py", line 1375, in http_open
    return self.do_open(http.client.HTTPConnection, req)
  File "/usr/lib/python3.9/urllib/request.py", line 1349, in do_open
    raise URLError(err)
urllib.error.URLError: <urlopen error [Errno 111] Connection refused>
2024-11-21 16:06:56,740 [INFO] Freezing in a spot
2024-11-21 16:06:56,741 [INFO] Connection attempt 4, max_reconnection_attempts 180
2024-11-21 16:06:57,796 [ERROR] ConnectionWatchdog - Network is unreachable: 
Traceback (most recent call last):
  File "/usr/lib/python3.9/urllib/request.py", line 1346, in do_open
    h.request(req.get_method(), req.selector, req.data, headers,
  File "/usr/lib/python3.9/http/client.py", line 1255, in request
    self._send_request(method, url, body, headers, encode_chunked)
  File "/usr/lib/python3.9/http/client.py", line 1301, in _send_request
    self.endheaders(body, encode_chunked=encode_chunked)
  File "/usr/lib/python3.9/http/client.py", line 1250, in endheaders
    self._send_output(message_body, encode_chunked=encode_chunked)
  File "/usr/lib/python3.9/http/client.py", line 1010, in _send_output
    self.send(msg)
  File "/usr/lib/python3.9/http/client.py", line 950, in send
    self.connect()
  File "/usr/lib/python3.9/http/client.py", line 921, in connect
    self.sock = self._create_connection(
  File "/usr/lib/python3.9/socket.py", line 843, in create_connection
    raise err
  File "/usr/lib/python3.9/socket.py", line 831, in create_connection
    sock.connect(sa)
ConnectionRefusedError: [Errno 111] Connection refused

During handling of the above exception, another exception occurred:

Traceback (most recent call last):
  File "/home/gourav/raspi-app/connection_watchdog.py", line 40, in is_internet_on
    urlopen(str('http://' + self.host_ip), timeout=5)
  File "/usr/lib/python3.9/urllib/request.py", line 214, in urlopen
    return opener.open(url, data, timeout)
  File "/usr/lib/python3.9/urllib/request.py", line 517, in open
    response = self._open(req, data)
  File "/usr/lib/python3.9/urllib/request.py", line 534, in _open
    result = self._call_chain(self.handle_open, protocol, protocol +
  File "/usr/lib/python3.9/urllib/request.py", line 494, in _call_chain
    result = func(*args)
  File "/usr/lib/python3.9/urllib/request.py", line 1375, in http_open
    return self.do_open(http.client.HTTPConnection, req)
  File "/usr/lib/python3.9/urllib/request.py", line 1349, in do_open
    raise URLError(err)
urllib.error.URLError: <urlopen error [Errno 111] Connection refused>
2024-11-21 16:06:57,798 [INFO] Freezing in a spot
2024-11-21 16:06:57,799 [INFO] Connection attempt 5, max_reconnection_attempts 180
2024-11-21 16:06:58,855 [ERROR] ConnectionWatchdog - Network is unreachable: 
Traceback (most recent call last):
  File "/usr/lib/python3.9/urllib/request.py", line 1346, in do_open
    h.request(req.get_method(), req.selector, req.data, headers,
  File "/usr/lib/python3.9/http/client.py", line 1255, in request
    self._send_request(method, url, body, headers, encode_chunked)
  File "/usr/lib/python3.9/http/client.py", line 1301, in _send_request
    self.endheaders(body, encode_chunked=encode_chunked)
  File "/usr/lib/python3.9/http/client.py", line 1250, in endheaders
    self._send_output(message_body, encode_chunked=encode_chunked)
  File "/usr/lib/python3.9/http/client.py", line 1010, in _send_output
    self.send(msg)
  File "/usr/lib/python3.9/http/client.py", line 950, in send
    self.connect()
  File "/usr/lib/python3.9/http/client.py", line 921, in connect
    self.sock = self._create_connection(
  File "/usr/lib/python3.9/socket.py", line 843, in create_connection
    raise err
  File "/usr/lib/python3.9/socket.py", line 831, in create_connection
    sock.connect(sa)
ConnectionRefusedError: [Errno 111] Connection refused

During handling of the above exception, another exception occurred:

Traceback (most recent call last):
  File "/home/gourav/raspi-app/connection_watchdog.py", line 40, in is_internet_on
    urlopen(str('http://' + self.host_ip), timeout=5)
  File "/usr/lib/python3.9/urllib/request.py", line 214, in urlopen
    return opener.open(url, data, timeout)
  File "/usr/lib/python3.9/urllib/request.py", line 517, in open
    response = self._open(req, data)
  File "/usr/lib/python3.9/urllib/request.py", line 534, in _open
    result = self._call_chain(self.handle_open, protocol, protocol +
  File "/usr/lib/python3.9/urllib/request.py", line 494, in _call_chain
    result = func(*args)
  File "/usr/lib/python3.9/urllib/request.py", line 1375, in http_open
    return self.do_open(http.client.HTTPConnection, req)
  File "/usr/lib/python3.9/urllib/request.py", line 1349, in do_open
    raise URLError(err)
urllib.error.URLError: <urlopen error [Errno 111] Connection refused>
2024-11-21 16:06:58,858 [INFO] Freezing in a spot
2024-11-21 16:06:58,860 [INFO] Connection attempt 6, max_reconnection_attempts 180
2024-11-21 16:06:59,947 [ERROR] ConnectionWatchdog - Network is unreachable: 
Traceback (most recent call last):
  File "/usr/lib/python3.9/urllib/request.py", line 1346, in do_open
    h.request(req.get_method(), req.selector, req.data, headers,
  File "/usr/lib/python3.9/http/client.py", line 1255, in request
    self._send_request(method, url, body, headers, encode_chunked)
  File "/usr/lib/python3.9/http/client.py", line 1301, in _send_request
    self.endheaders(body, encode_chunked=encode_chunked)
  File "/usr/lib/python3.9/http/client.py", line 1250, in endheaders
    self._send_output(message_body, encode_chunked=encode_chunked)
  File "/usr/lib/python3.9/http/client.py", line 1010, in _send_output
    self.send(msg)
  File "/usr/lib/python3.9/http/client.py", line 950, in send
    self.connect()
  File "/usr/lib/python3.9/http/client.py", line 921, in connect
    self.sock = self._create_connection(
  File "/usr/lib/python3.9/socket.py", line 843, in create_connection
    raise err
  File "/usr/lib/python3.9/socket.py", line 831, in create_connection
    sock.connect(sa)
ConnectionRefusedError: [Errno 111] Connection refused

During handling of the above exception, another exception occurred:

Traceback (most recent call last):
  File "/home/gourav/raspi-app/connection_watchdog.py", line 40, in is_internet_on
    urlopen(str('http://' + self.host_ip), timeout=5)
  File "/usr/lib/python3.9/urllib/request.py", line 214, in urlopen
    return opener.open(url, data, timeout)
  File "/usr/lib/python3.9/urllib/request.py", line 517, in open
    response = self._open(req, data)
  File "/usr/lib/python3.9/urllib/request.py", line 534, in _open
    result = self._call_chain(self.handle_open, protocol, protocol +
  File "/usr/lib/python3.9/urllib/request.py", line 494, in _call_chain
    result = func(*args)
  File "/usr/lib/python3.9/urllib/request.py", line 1375, in http_open
    return self.do_open(http.client.HTTPConnection, req)
  File "/usr/lib/python3.9/urllib/request.py", line 1349, in do_open
    raise URLError(err)
urllib.error.URLError: <urlopen error [Errno 111] Connection refused>
2024-11-21 16:06:59,949 [INFO] Freezing in a spot
2024-11-21 16:06:59,951 [INFO] Connection attempt 7, max_reconnection_attempts 180
2024-11-21 16:07:01,037 [ERROR] ConnectionWatchdog - Network is unreachable: 
Traceback (most recent call last):
  File "/usr/lib/python3.9/urllib/request.py", line 1346, in do_open
    h.request(req.get_method(), req.selector, req.data, headers,
  File "/usr/lib/python3.9/http/client.py", line 1255, in request
    self._send_request(method, url, body, headers, encode_chunked)
  File "/usr/lib/python3.9/http/client.py", line 1301, in _send_request
    self.endheaders(body, encode_chunked=encode_chunked)
  File "/usr/lib/python3.9/http/client.py", line 1250, in endheaders
    self._send_output(message_body, encode_chunked=encode_chunked)
  File "/usr/lib/python3.9/http/client.py", line 1010, in _send_output
    self.send(msg)
  File "/usr/lib/python3.9/http/client.py", line 950, in send
    self.connect()
  File "/usr/lib/python3.9/http/client.py", line 921, in connect
    self.sock = self._create_connection(
  File "/usr/lib/python3.9/socket.py", line 843, in create_connection
    raise err
  File "/usr/lib/python3.9/socket.py", line 831, in create_connection
    sock.connect(sa)
ConnectionRefusedError: [Errno 111] Connection refused

During handling of the above exception, another exception occurred:

Traceback (most recent call last):
  File "/home/gourav/raspi-app/connection_watchdog.py", line 40, in is_internet_on
    urlopen(str('http://' + self.host_ip), timeout=5)
  File "/usr/lib/python3.9/urllib/request.py", line 214, in urlopen
    return opener.open(url, data, timeout)
  File "/usr/lib/python3.9/urllib/request.py", line 517, in open
    response = self._open(req, data)
  File "/usr/lib/python3.9/urllib/request.py", line 534, in _open
    result = self._call_chain(self.handle_open, protocol, protocol +
  File "/usr/lib/python3.9/urllib/request.py", line 494, in _call_chain
    result = func(*args)
  File "/usr/lib/python3.9/urllib/request.py", line 1375, in http_open
    return self.do_open(http.client.HTTPConnection, req)
  File "/usr/lib/python3.9/urllib/request.py", line 1349, in do_open
    raise URLError(err)
urllib.error.URLError: <urlopen error [Errno 111] Connection refused>
2024-11-21 16:07:01,039 [INFO] Freezing in a spot
2024-11-21 16:07:01,040 [INFO] Connection attempt 8, max_reconnection_attempts 180
2024-11-21 16:07:02,136 [ERROR] ConnectionWatchdog - Network is unreachable: 
Traceback (most recent call last):
  File "/usr/lib/python3.9/urllib/request.py", line 1346, in do_open
    h.request(req.get_method(), req.selector, req.data, headers,
  File "/usr/lib/python3.9/http/client.py", line 1255, in request
    self._send_request(method, url, body, headers, encode_chunked)
  File "/usr/lib/python3.9/http/client.py", line 1301, in _send_request
    self.endheaders(body, encode_chunked=encode_chunked)
  File "/usr/lib/python3.9/http/client.py", line 1250, in endheaders
    self._send_output(message_body, encode_chunked=encode_chunked)
  File "/usr/lib/python3.9/http/client.py", line 1010, in _send_output
    self.send(msg)
  File "/usr/lib/python3.9/http/client.py", line 950, in send
    self.connect()
  File "/usr/lib/python3.9/http/client.py", line 921, in connect
    self.sock = self._create_connection(
  File "/usr/lib/python3.9/socket.py", line 843, in create_connection
    raise err
  File "/usr/lib/python3.9/socket.py", line 831, in create_connection
    sock.connect(sa)
ConnectionRefusedError: [Errno 111] Connection refused

During handling of the above exception, another exception occurred:

Traceback (most recent call last):
  File "/home/gourav/raspi-app/connection_watchdog.py", line 40, in is_internet_on
    urlopen(str('http://' + self.host_ip), timeout=5)
  File "/usr/lib/python3.9/urllib/request.py", line 214, in urlopen
    return opener.open(url, data, timeout)
  File "/usr/lib/python3.9/urllib/request.py", line 517, in open
    response = self._open(req, data)
  File "/usr/lib/python3.9/urllib/request.py", line 534, in _open
    result = self._call_chain(self.handle_open, protocol, protocol +
  File "/usr/lib/python3.9/urllib/request.py", line 494, in _call_chain
    result = func(*args)
  File "/usr/lib/python3.9/urllib/request.py", line 1375, in http_open
    return self.do_open(http.client.HTTPConnection, req)
  File "/usr/lib/python3.9/urllib/request.py", line 1349, in do_open
    raise URLError(err)
urllib.error.URLError: <urlopen error [Errno 111] Connection refused>
2024-11-21 16:07:02,140 [INFO] Freezing in a spot
2024-11-21 16:07:02,141 [INFO] Connection attempt 9, max_reconnection_attempts 180
2024-11-21 16:07:03,279 [ERROR] ConnectionWatchdog - Network is unreachable: 
Traceback (most recent call last):
  File "/usr/lib/python3.9/urllib/request.py", line 1346, in do_open
    h.request(req.get_method(), req.selector, req.data, headers,
  File "/usr/lib/python3.9/http/client.py", line 1255, in request
    self._send_request(method, url, body, headers, encode_chunked)
  File "/usr/lib/python3.9/http/client.py", line 1301, in _send_request
    self.endheaders(body, encode_chunked=encode_chunked)
  File "/usr/lib/python3.9/http/client.py", line 1250, in endheaders
    self._send_output(message_body, encode_chunked=encode_chunked)
  File "/usr/lib/python3.9/http/client.py", line 1010, in _send_output
    self.send(msg)
  File "/usr/lib/python3.9/http/client.py", line 950, in send
    self.connect()
  File "/usr/lib/python3.9/http/client.py", line 921, in connect
    self.sock = self._create_connection(
  File "/usr/lib/python3.9/socket.py", line 843, in create_connection
    raise err
  File "/usr/lib/python3.9/socket.py", line 831, in create_connection
    sock.connect(sa)
ConnectionRefusedError: [Errno 111] Connection refused

During handling of the above exception, another exception occurred:

Traceback (most recent call last):
  File "/home/gourav/raspi-app/connection_watchdog.py", line 40, in is_internet_on
    urlopen(str('http://' + self.host_ip), timeout=5)
  File "/usr/lib/python3.9/urllib/request.py", line 214, in urlopen
    return opener.open(url, data, timeout)
  File "/usr/lib/python3.9/urllib/request.py", line 517, in open
    response = self._open(req, data)
  File "/usr/lib/python3.9/urllib/request.py", line 534, in _open
    result = self._call_chain(self.handle_open, protocol, protocol +
  File "/usr/lib/python3.9/urllib/request.py", line 494, in _call_chain
    result = func(*args)
  File "/usr/lib/python3.9/urllib/request.py", line 1375, in http_open
    return self.do_open(http.client.HTTPConnection, req)
  File "/usr/lib/python3.9/urllib/request.py", line 1349, in do_open
    raise URLError(err)
urllib.error.URLError: <urlopen error [Errno 111] Connection refused>
2024-11-21 16:07:03,282 [INFO] Freezing in a spot
2024-11-21 16:07:03,283 [INFO] Connection attempt 10, max_reconnection_attempts 180
