2024-11-21 14:18:06,095 [DEBUG] DroneApp has started! Directory ./
2024-11-21 14:18:07,056 [INFO] Barometer 1 calibration complete
2024-11-21 14:18:07,057 [INFO] Barometer 2 calibration complete
2024-11-21 14:18:07,149 [INFO] ArduCopter V4.6.0-dev (3764f377)
2024-11-21 14:18:07,150 [INFO] 08849941057b4f329db74127f3309984
2024-11-21 14:18:07,151 [INFO] Frame: QUAD/PLUS
2024-11-21 14:18:07,527 [INFO] ArduPilot Ready
2024-11-21 14:18:07,527 [INFO] AHRS: DCM active
2024-11-21 14:18:07,921 [INFO] RC7: SaveWaypoint LOW
2024-11-21 14:18:08,227 [DEBUG] Still waiting for data from vehicle: parameters
2024-11-21 14:18:08,328 [INFO] Connected to Simulator On Port: 14553 
2024-11-21 14:18:08,329 [INFO] Engine started
2024-11-21 14:18:08,329 [INFO] Drone connected
2024-11-21 14:18:09,592 [INFO] EKF3 IMU0 initialised
2024-11-21 14:18:09,593 [INFO] EKF3 IMU1 initialised
2024-11-21 14:18:09,594 [INFO] AHRS: EKF3 active
2024-11-21 14:18:10,870 [INFO] EKF3 IMU1 tilt alignment complete
2024-11-21 14:18:10,874 [INFO] EKF3 IMU0 tilt alignment complete
2024-11-21 14:18:11,021 [INFO] EKF3 IMU1 MAG0 initial yaw alignment complete
2024-11-21 14:18:11,022 [INFO] EKF3 IMU0 MAG0 initial yaw alignment complete
2024-11-21 14:18:13,447 [ERROR] ConnectionWatchdog - Network is unreachable: 
Traceback (most recent call last):
  File "/usr/lib/python3.9/urllib/request.py", line 1346, in do_open
    h.request(req.get_method(), req.selector, req.data, headers,
  File "/usr/lib/python3.9/http/client.py", line 1255, in request
    self._send_request(method, url, body, headers, encode_chunked)
  File "/usr/lib/python3.9/http/client.py", line 1301, in _send_request
    self.endheaders(body, encode_chunked=encode_chunked)
  File "/usr/lib/python3.9/http/client.py", line 1250, in endheaders
    self._send_output(message_body, encode_chunked=encode_chunked)
  File "/usr/lib/python3.9/http/client.py", line 1010, in _send_output
    self.send(msg)
  File "/usr/lib/python3.9/http/client.py", line 950, in send
    self.connect()
  File "/usr/lib/python3.9/http/client.py", line 921, in connect
    self.sock = self._create_connection(
  File "/usr/lib/python3.9/socket.py", line 843, in create_connection
    raise err
  File "/usr/lib/python3.9/socket.py", line 831, in create_connection
    sock.connect(sa)
ConnectionRefusedError: [Errno 111] Connection refused

During handling of the above exception, another exception occurred:

Traceback (most recent call last):
  File "/home/gourav/raspi-app/connection_watchdog.py", line 40, in is_internet_on
    urlopen(str('http://' + self.host_ip), timeout=5)
  File "/usr/lib/python3.9/urllib/request.py", line 214, in urlopen
    return opener.open(url, data, timeout)
  File "/usr/lib/python3.9/urllib/request.py", line 517, in open
    response = self._open(req, data)
  File "/usr/lib/python3.9/urllib/request.py", line 534, in _open
    result = self._call_chain(self.handle_open, protocol, protocol +
  File "/usr/lib/python3.9/urllib/request.py", line 494, in _call_chain
    result = func(*args)
  File "/usr/lib/python3.9/urllib/request.py", line 1375, in http_open
    return self.do_open(http.client.HTTPConnection, req)
  File "/usr/lib/python3.9/urllib/request.py", line 1349, in do_open
    raise URLError(err)
urllib.error.URLError: <urlopen error [Errno 111] Connection refused>
2024-11-21 14:18:13,459 [INFO] Freezing in a spot
2024-11-21 14:18:13,460 [INFO] Connection attempt 1, max_reconnection_attempts 180
2024-11-21 14:18:14,521 [ERROR] ConnectionWatchdog - Network is unreachable: 
Traceback (most recent call last):
  File "/usr/lib/python3.9/urllib/request.py", line 1346, in do_open
    h.request(req.get_method(), req.selector, req.data, headers,
  File "/usr/lib/python3.9/http/client.py", line 1255, in request
    self._send_request(method, url, body, headers, encode_chunked)
  File "/usr/lib/python3.9/http/client.py", line 1301, in _send_request
    self.endheaders(body, encode_chunked=encode_chunked)
  File "/usr/lib/python3.9/http/client.py", line 1250, in endheaders
    self._send_output(message_body, encode_chunked=encode_chunked)
  File "/usr/lib/python3.9/http/client.py", line 1010, in _send_output
    self.send(msg)
  File "/usr/lib/python3.9/http/client.py", line 950, in send
    self.connect()
  File "/usr/lib/python3.9/http/client.py", line 921, in connect
    self.sock = self._create_connection(
  File "/usr/lib/python3.9/socket.py", line 843, in create_connection
    raise err
  File "/usr/lib/python3.9/socket.py", line 831, in create_connection
    sock.connect(sa)
ConnectionRefusedError: [Errno 111] Connection refused

During handling of the above exception, another exception occurred:

Traceback (most recent call last):
  File "/home/gourav/raspi-app/connection_watchdog.py", line 40, in is_internet_on
    urlopen(str('http://' + self.host_ip), timeout=5)
  File "/usr/lib/python3.9/urllib/request.py", line 214, in urlopen
    return opener.open(url, data, timeout)
  File "/usr/lib/python3.9/urllib/request.py", line 517, in open
    response = self._open(req, data)
  File "/usr/lib/python3.9/urllib/request.py", line 534, in _open
    result = self._call_chain(self.handle_open, protocol, protocol +
  File "/usr/lib/python3.9/urllib/request.py", line 494, in _call_chain
    result = func(*args)
  File "/usr/lib/python3.9/urllib/request.py", line 1375, in http_open
    return self.do_open(http.client.HTTPConnection, req)
  File "/usr/lib/python3.9/urllib/request.py", line 1349, in do_open
    raise URLError(err)
urllib.error.URLError: <urlopen error [Errno 111] Connection refused>
2024-11-21 14:18:14,526 [INFO] Freezing in a spot
2024-11-21 14:18:14,527 [INFO] Connection attempt 2, max_reconnection_attempts 180
2024-11-21 14:18:14,903 [INFO] GPS 1: probing for u-blox at 230400 baud
2024-11-21 14:18:14,905 [INFO] GPS 1: detected u-blox
2024-11-21 14:18:15,624 [ERROR] ConnectionWatchdog - Network is unreachable: 
Traceback (most recent call last):
  File "/usr/lib/python3.9/urllib/request.py", line 1346, in do_open
    h.request(req.get_method(), req.selector, req.data, headers,
  File "/usr/lib/python3.9/http/client.py", line 1255, in request
    self._send_request(method, url, body, headers, encode_chunked)
  File "/usr/lib/python3.9/http/client.py", line 1301, in _send_request
    self.endheaders(body, encode_chunked=encode_chunked)
  File "/usr/lib/python3.9/http/client.py", line 1250, in endheaders
    self._send_output(message_body, encode_chunked=encode_chunked)
  File "/usr/lib/python3.9/http/client.py", line 1010, in _send_output
    self.send(msg)
  File "/usr/lib/python3.9/http/client.py", line 950, in send
    self.connect()
  File "/usr/lib/python3.9/http/client.py", line 921, in connect
    self.sock = self._create_connection(
  File "/usr/lib/python3.9/socket.py", line 843, in create_connection
    raise err
  File "/usr/lib/python3.9/socket.py", line 831, in create_connection
    sock.connect(sa)
ConnectionRefusedError: [Errno 111] Connection refused

During handling of the above exception, another exception occurred:

Traceback (most recent call last):
  File "/home/gourav/raspi-app/connection_watchdog.py", line 40, in is_internet_on
    urlopen(str('http://' + self.host_ip), timeout=5)
  File "/usr/lib/python3.9/urllib/request.py", line 214, in urlopen
    return opener.open(url, data, timeout)
  File "/usr/lib/python3.9/urllib/request.py", line 517, in open
    response = self._open(req, data)
  File "/usr/lib/python3.9/urllib/request.py", line 534, in _open
    result = self._call_chain(self.handle_open, protocol, protocol +
  File "/usr/lib/python3.9/urllib/request.py", line 494, in _call_chain
    result = func(*args)
  File "/usr/lib/python3.9/urllib/request.py", line 1375, in http_open
    return self.do_open(http.client.HTTPConnection, req)
  File "/usr/lib/python3.9/urllib/request.py", line 1349, in do_open
    raise URLError(err)
urllib.error.URLError: <urlopen error [Errno 111] Connection refused>
2024-11-21 14:18:15,627 [INFO] Freezing in a spot
2024-11-21 14:18:15,628 [INFO] Connection attempt 3, max_reconnection_attempts 180
2024-11-21 14:18:16,777 [ERROR] ConnectionWatchdog - Network is unreachable: 
Traceback (most recent call last):
  File "/usr/lib/python3.9/urllib/request.py", line 1346, in do_open
    h.request(req.get_method(), req.selector, req.data, headers,
  File "/usr/lib/python3.9/http/client.py", line 1255, in request
    self._send_request(method, url, body, headers, encode_chunked)
  File "/usr/lib/python3.9/http/client.py", line 1301, in _send_request
    self.endheaders(body, encode_chunked=encode_chunked)
  File "/usr/lib/python3.9/http/client.py", line 1250, in endheaders
    self._send_output(message_body, encode_chunked=encode_chunked)
  File "/usr/lib/python3.9/http/client.py", line 1010, in _send_output
    self.send(msg)
  File "/usr/lib/python3.9/http/client.py", line 950, in send
    self.connect()
  File "/usr/lib/python3.9/http/client.py", line 921, in connect
    self.sock = self._create_connection(
  File "/usr/lib/python3.9/socket.py", line 843, in create_connection
    raise err
  File "/usr/lib/python3.9/socket.py", line 831, in create_connection
    sock.connect(sa)
ConnectionRefusedError: [Errno 111] Connection refused

During handling of the above exception, another exception occurred:

Traceback (most recent call last):
  File "/home/gourav/raspi-app/connection_watchdog.py", line 40, in is_internet_on
    urlopen(str('http://' + self.host_ip), timeout=5)
  File "/usr/lib/python3.9/urllib/request.py", line 214, in urlopen
    return opener.open(url, data, timeout)
  File "/usr/lib/python3.9/urllib/request.py", line 517, in open
    response = self._open(req, data)
  File "/usr/lib/python3.9/urllib/request.py", line 534, in _open
    result = self._call_chain(self.handle_open, protocol, protocol +
  File "/usr/lib/python3.9/urllib/request.py", line 494, in _call_chain
    result = func(*args)
  File "/usr/lib/python3.9/urllib/request.py", line 1375, in http_open
    return self.do_open(http.client.HTTPConnection, req)
  File "/usr/lib/python3.9/urllib/request.py", line 1349, in do_open
    raise URLError(err)
urllib.error.URLError: <urlopen error [Errno 111] Connection refused>
2024-11-21 14:18:16,782 [INFO] Freezing in a spot
2024-11-21 14:18:16,784 [INFO] Connection attempt 4, max_reconnection_attempts 180
2024-11-21 14:18:17,883 [ERROR] ConnectionWatchdog - Network is unreachable: 
Traceback (most recent call last):
  File "/usr/lib/python3.9/urllib/request.py", line 1346, in do_open
    h.request(req.get_method(), req.selector, req.data, headers,
  File "/usr/lib/python3.9/http/client.py", line 1255, in request
    self._send_request(method, url, body, headers, encode_chunked)
  File "/usr/lib/python3.9/http/client.py", line 1301, in _send_request
    self.endheaders(body, encode_chunked=encode_chunked)
  File "/usr/lib/python3.9/http/client.py", line 1250, in endheaders
    self._send_output(message_body, encode_chunked=encode_chunked)
  File "/usr/lib/python3.9/http/client.py", line 1010, in _send_output
    self.send(msg)
  File "/usr/lib/python3.9/http/client.py", line 950, in send
    self.connect()
  File "/usr/lib/python3.9/http/client.py", line 921, in connect
    self.sock = self._create_connection(
  File "/usr/lib/python3.9/socket.py", line 843, in create_connection
    raise err
  File "/usr/lib/python3.9/socket.py", line 831, in create_connection
    sock.connect(sa)
ConnectionRefusedError: [Errno 111] Connection refused

During handling of the above exception, another exception occurred:

Traceback (most recent call last):
  File "/home/gourav/raspi-app/connection_watchdog.py", line 40, in is_internet_on
    urlopen(str('http://' + self.host_ip), timeout=5)
  File "/usr/lib/python3.9/urllib/request.py", line 214, in urlopen
    return opener.open(url, data, timeout)
  File "/usr/lib/python3.9/urllib/request.py", line 517, in open
    response = self._open(req, data)
  File "/usr/lib/python3.9/urllib/request.py", line 534, in _open
    result = self._call_chain(self.handle_open, protocol, protocol +
  File "/usr/lib/python3.9/urllib/request.py", line 494, in _call_chain
    result = func(*args)
  File "/usr/lib/python3.9/urllib/request.py", line 1375, in http_open
    return self.do_open(http.client.HTTPConnection, req)
  File "/usr/lib/python3.9/urllib/request.py", line 1349, in do_open
    raise URLError(err)
urllib.error.URLError: <urlopen error [Errno 111] Connection refused>
2024-11-21 14:18:17,887 [INFO] Freezing in a spot
2024-11-21 14:18:17,889 [INFO] Connection attempt 5, max_reconnection_attempts 180
2024-11-21 14:18:18,983 [ERROR] ConnectionWatchdog - Network is unreachable: 
Traceback (most recent call last):
  File "/usr/lib/python3.9/urllib/request.py", line 1346, in do_open
    h.request(req.get_method(), req.selector, req.data, headers,
  File "/usr/lib/python3.9/http/client.py", line 1255, in request
    self._send_request(method, url, body, headers, encode_chunked)
  File "/usr/lib/python3.9/http/client.py", line 1301, in _send_request
    self.endheaders(body, encode_chunked=encode_chunked)
  File "/usr/lib/python3.9/http/client.py", line 1250, in endheaders
    self._send_output(message_body, encode_chunked=encode_chunked)
  File "/usr/lib/python3.9/http/client.py", line 1010, in _send_output
    self.send(msg)
  File "/usr/lib/python3.9/http/client.py", line 950, in send
    self.connect()
  File "/usr/lib/python3.9/http/client.py", line 921, in connect
    self.sock = self._create_connection(
  File "/usr/lib/python3.9/socket.py", line 843, in create_connection
    raise err
  File "/usr/lib/python3.9/socket.py", line 831, in create_connection
    sock.connect(sa)
ConnectionRefusedError: [Errno 111] Connection refused

During handling of the above exception, another exception occurred:

Traceback (most recent call last):
  File "/home/gourav/raspi-app/connection_watchdog.py", line 40, in is_internet_on
    urlopen(str('http://' + self.host_ip), timeout=5)
  File "/usr/lib/python3.9/urllib/request.py", line 214, in urlopen
    return opener.open(url, data, timeout)
  File "/usr/lib/python3.9/urllib/request.py", line 517, in open
    response = self._open(req, data)
  File "/usr/lib/python3.9/urllib/request.py", line 534, in _open
    result = self._call_chain(self.handle_open, protocol, protocol +
  File "/usr/lib/python3.9/urllib/request.py", line 494, in _call_chain
    result = func(*args)
  File "/usr/lib/python3.9/urllib/request.py", line 1375, in http_open
    return self.do_open(http.client.HTTPConnection, req)
  File "/usr/lib/python3.9/urllib/request.py", line 1349, in do_open
    raise URLError(err)
urllib.error.URLError: <urlopen error [Errno 111] Connection refused>
2024-11-21 14:18:18,985 [INFO] Freezing in a spot
2024-11-21 14:18:18,985 [INFO] Connection attempt 6, max_reconnection_attempts 180
2024-11-21 14:18:20,047 [ERROR] ConnectionWatchdog - Network is unreachable: 
Traceback (most recent call last):
  File "/usr/lib/python3.9/urllib/request.py", line 1346, in do_open
    h.request(req.get_method(), req.selector, req.data, headers,
  File "/usr/lib/python3.9/http/client.py", line 1255, in request
    self._send_request(method, url, body, headers, encode_chunked)
  File "/usr/lib/python3.9/http/client.py", line 1301, in _send_request
    self.endheaders(body, encode_chunked=encode_chunked)
  File "/usr/lib/python3.9/http/client.py", line 1250, in endheaders
    self._send_output(message_body, encode_chunked=encode_chunked)
  File "/usr/lib/python3.9/http/client.py", line 1010, in _send_output
    self.send(msg)
  File "/usr/lib/python3.9/http/client.py", line 950, in send
    self.connect()
  File "/usr/lib/python3.9/http/client.py", line 921, in connect
    self.sock = self._create_connection(
  File "/usr/lib/python3.9/socket.py", line 843, in create_connection
    raise err
  File "/usr/lib/python3.9/socket.py", line 831, in create_connection
    sock.connect(sa)
ConnectionRefusedError: [Errno 111] Connection refused

During handling of the above exception, another exception occurred:

Traceback (most recent call last):
  File "/home/gourav/raspi-app/connection_watchdog.py", line 40, in is_internet_on
    urlopen(str('http://' + self.host_ip), timeout=5)
  File "/usr/lib/python3.9/urllib/request.py", line 214, in urlopen
    return opener.open(url, data, timeout)
  File "/usr/lib/python3.9/urllib/request.py", line 517, in open
    response = self._open(req, data)
  File "/usr/lib/python3.9/urllib/request.py", line 534, in _open
    result = self._call_chain(self.handle_open, protocol, protocol +
  File "/usr/lib/python3.9/urllib/request.py", line 494, in _call_chain
    result = func(*args)
  File "/usr/lib/python3.9/urllib/request.py", line 1375, in http_open
    return self.do_open(http.client.HTTPConnection, req)
  File "/usr/lib/python3.9/urllib/request.py", line 1349, in do_open
    raise URLError(err)
urllib.error.URLError: <urlopen error [Errno 111] Connection refused>
2024-11-21 14:18:20,048 [INFO] Freezing in a spot
2024-11-21 14:18:20,049 [INFO] Connection attempt 7, max_reconnection_attempts 180
2024-11-21 14:18:24,045 [ERROR] ConnectionWatchdog - Network is unreachable: 
Traceback (most recent call last):
  File "/usr/lib/python3.9/urllib/request.py", line 1346, in do_open
    h.request(req.get_method(), req.selector, req.data, headers,
  File "/usr/lib/python3.9/http/client.py", line 1255, in request
    self._send_request(method, url, body, headers, encode_chunked)
  File "/usr/lib/python3.9/http/client.py", line 1301, in _send_request
    self.endheaders(body, encode_chunked=encode_chunked)
  File "/usr/lib/python3.9/http/client.py", line 1250, in endheaders
    self._send_output(message_body, encode_chunked=encode_chunked)
  File "/usr/lib/python3.9/http/client.py", line 1010, in _send_output
    self.send(msg)
  File "/usr/lib/python3.9/http/client.py", line 950, in send
    self.connect()
  File "/usr/lib/python3.9/http/client.py", line 921, in connect
    self.sock = self._create_connection(
  File "/usr/lib/python3.9/socket.py", line 843, in create_connection
    raise err
  File "/usr/lib/python3.9/socket.py", line 831, in create_connection
    sock.connect(sa)
ConnectionRefusedError: [Errno 111] Connection refused

During handling of the above exception, another exception occurred:

Traceback (most recent call last):
  File "/home/gourav/raspi-app/connection_watchdog.py", line 40, in is_internet_on
    urlopen(str('http://' + self.host_ip), timeout=5)
  File "/usr/lib/python3.9/urllib/request.py", line 214, in urlopen
    return opener.open(url, data, timeout)
  File "/usr/lib/python3.9/urllib/request.py", line 517, in open
    response = self._open(req, data)
  File "/usr/lib/python3.9/urllib/request.py", line 534, in _open
    result = self._call_chain(self.handle_open, protocol, protocol +
  File "/usr/lib/python3.9/urllib/request.py", line 494, in _call_chain
    result = func(*args)
  File "/usr/lib/python3.9/urllib/request.py", line 1375, in http_open
    return self.do_open(http.client.HTTPConnection, req)
  File "/usr/lib/python3.9/urllib/request.py", line 1349, in do_open
    raise URLError(err)
urllib.error.URLError: <urlopen error [Errno 111] Connection refused>
2024-11-21 14:18:24,048 [INFO] Freezing in a spot
2024-11-21 14:18:24,050 [INFO] Connection attempt 8, max_reconnection_attempts 180
2024-11-21 14:18:25,104 [INFO] EKF3 IMU1 origin set
2024-11-21 14:18:25,122 [ERROR] ConnectionWatchdog - Network is unreachable: 
Traceback (most recent call last):
  File "/usr/lib/python3.9/urllib/request.py", line 1346, in do_open
    h.request(req.get_method(), req.selector, req.data, headers,
  File "/usr/lib/python3.9/http/client.py", line 1255, in request
    self._send_request(method, url, body, headers, encode_chunked)
  File "/usr/lib/python3.9/http/client.py", line 1301, in _send_request
    self.endheaders(body, encode_chunked=encode_chunked)
  File "/usr/lib/python3.9/http/client.py", line 1250, in endheaders
    self._send_output(message_body, encode_chunked=encode_chunked)
  File "/usr/lib/python3.9/http/client.py", line 1010, in _send_output
    self.send(msg)
  File "/usr/lib/python3.9/http/client.py", line 950, in send
    self.connect()
  File "/usr/lib/python3.9/http/client.py", line 921, in connect
    self.sock = self._create_connection(
  File "/usr/lib/python3.9/socket.py", line 843, in create_connection
    raise err
  File "/usr/lib/python3.9/socket.py", line 831, in create_connection
    sock.connect(sa)
ConnectionRefusedError: [Errno 111] Connection refused

During handling of the above exception, another exception occurred:

Traceback (most recent call last):
  File "/home/gourav/raspi-app/connection_watchdog.py", line 40, in is_internet_on
    urlopen(str('http://' + self.host_ip), timeout=5)
  File "/usr/lib/python3.9/urllib/request.py", line 214, in urlopen
    return opener.open(url, data, timeout)
  File "/usr/lib/python3.9/urllib/request.py", line 517, in open
    response = self._open(req, data)
  File "/usr/lib/python3.9/urllib/request.py", line 534, in _open
    result = self._call_chain(self.handle_open, protocol, protocol +
  File "/usr/lib/python3.9/urllib/request.py", line 494, in _call_chain
    result = func(*args)
  File "/usr/lib/python3.9/urllib/request.py", line 1375, in http_open
    return self.do_open(http.client.HTTPConnection, req)
  File "/usr/lib/python3.9/urllib/request.py", line 1349, in do_open
    raise URLError(err)
urllib.error.URLError: <urlopen error [Errno 111] Connection refused>
2024-11-21 14:18:25,125 [INFO] Freezing in a spot
2024-11-21 14:18:25,126 [INFO] Connection attempt 9, max_reconnection_attempts 180
2024-11-21 14:18:25,132 [INFO] Field Elevation Set: 584m
2024-11-21 14:18:25,291 [INFO] EKF3 IMU0 origin set
2024-11-21 14:18:26,245 [ERROR] ConnectionWatchdog - Network is unreachable: 
Traceback (most recent call last):
  File "/usr/lib/python3.9/urllib/request.py", line 1346, in do_open
    h.request(req.get_method(), req.selector, req.data, headers,
  File "/usr/lib/python3.9/http/client.py", line 1255, in request
    self._send_request(method, url, body, headers, encode_chunked)
  File "/usr/lib/python3.9/http/client.py", line 1301, in _send_request
    self.endheaders(body, encode_chunked=encode_chunked)
  File "/usr/lib/python3.9/http/client.py", line 1250, in endheaders
    self._send_output(message_body, encode_chunked=encode_chunked)
  File "/usr/lib/python3.9/http/client.py", line 1010, in _send_output
    self.send(msg)
  File "/usr/lib/python3.9/http/client.py", line 950, in send
    self.connect()
  File "/usr/lib/python3.9/http/client.py", line 921, in connect
    self.sock = self._create_connection(
  File "/usr/lib/python3.9/socket.py", line 843, in create_connection
    raise err
  File "/usr/lib/python3.9/socket.py", line 831, in create_connection
    sock.connect(sa)
ConnectionRefusedError: [Errno 111] Connection refused

During handling of the above exception, another exception occurred:

Traceback (most recent call last):
  File "/home/gourav/raspi-app/connection_watchdog.py", line 40, in is_internet_on
    urlopen(str('http://' + self.host_ip), timeout=5)
  File "/usr/lib/python3.9/urllib/request.py", line 214, in urlopen
    return opener.open(url, data, timeout)
  File "/usr/lib/python3.9/urllib/request.py", line 517, in open
    response = self._open(req, data)
  File "/usr/lib/python3.9/urllib/request.py", line 534, in _open
    result = self._call_chain(self.handle_open, protocol, protocol +
  File "/usr/lib/python3.9/urllib/request.py", line 494, in _call_chain
    result = func(*args)
  File "/usr/lib/python3.9/urllib/request.py", line 1375, in http_open
    return self.do_open(http.client.HTTPConnection, req)
  File "/usr/lib/python3.9/urllib/request.py", line 1349, in do_open
    raise URLError(err)
urllib.error.URLError: <urlopen error [Errno 111] Connection refused>
2024-11-21 14:18:26,248 [INFO] Freezing in a spot
2024-11-21 14:18:26,249 [INFO] Connection attempt 10, max_reconnection_attempts 180
2024-11-21 14:18:27,303 [ERROR] ConnectionWatchdog - Network is unreachable: 
Traceback (most recent call last):
  File "/usr/lib/python3.9/urllib/request.py", line 1346, in do_open
    h.request(req.get_method(), req.selector, req.data, headers,
  File "/usr/lib/python3.9/http/client.py", line 1255, in request
    self._send_request(method, url, body, headers, encode_chunked)
  File "/usr/lib/python3.9/http/client.py", line 1301, in _send_request
    self.endheaders(body, encode_chunked=encode_chunked)
  File "/usr/lib/python3.9/http/client.py", line 1250, in endheaders
    self._send_output(message_body, encode_chunked=encode_chunked)
  File "/usr/lib/python3.9/http/client.py", line 1010, in _send_output
    self.send(msg)
  File "/usr/lib/python3.9/http/client.py", line 950, in send
    self.connect()
  File "/usr/lib/python3.9/http/client.py", line 921, in connect
    self.sock = self._create_connection(
  File "/usr/lib/python3.9/socket.py", line 843, in create_connection
    raise err
  File "/usr/lib/python3.9/socket.py", line 831, in create_connection
    sock.connect(sa)
ConnectionRefusedError: [Errno 111] Connection refused

During handling of the above exception, another exception occurred:

Traceback (most recent call last):
  File "/home/gourav/raspi-app/connection_watchdog.py", line 40, in is_internet_on
    urlopen(str('http://' + self.host_ip), timeout=5)
  File "/usr/lib/python3.9/urllib/request.py", line 214, in urlopen
    return opener.open(url, data, timeout)
  File "/usr/lib/python3.9/urllib/request.py", line 517, in open
    response = self._open(req, data)
  File "/usr/lib/python3.9/urllib/request.py", line 534, in _open
    result = self._call_chain(self.handle_open, protocol, protocol +
  File "/usr/lib/python3.9/urllib/request.py", line 494, in _call_chain
    result = func(*args)
  File "/usr/lib/python3.9/urllib/request.py", line 1375, in http_open
    return self.do_open(http.client.HTTPConnection, req)
  File "/usr/lib/python3.9/urllib/request.py", line 1349, in do_open
    raise URLError(err)
urllib.error.URLError: <urlopen error [Errno 111] Connection refused>
2024-11-21 14:18:27,308 [INFO] Freezing in a spot
2024-11-21 14:18:27,310 [INFO] Connection attempt 11, max_reconnection_attempts 180
2024-11-21 14:18:28,363 [ERROR] ConnectionWatchdog - Network is unreachable: 
Traceback (most recent call last):
  File "/usr/lib/python3.9/urllib/request.py", line 1346, in do_open
    h.request(req.get_method(), req.selector, req.data, headers,
  File "/usr/lib/python3.9/http/client.py", line 1255, in request
    self._send_request(method, url, body, headers, encode_chunked)
  File "/usr/lib/python3.9/http/client.py", line 1301, in _send_request
    self.endheaders(body, encode_chunked=encode_chunked)
  File "/usr/lib/python3.9/http/client.py", line 1250, in endheaders
    self._send_output(message_body, encode_chunked=encode_chunked)
  File "/usr/lib/python3.9/http/client.py", line 1010, in _send_output
    self.send(msg)
  File "/usr/lib/python3.9/http/client.py", line 950, in send
    self.connect()
  File "/usr/lib/python3.9/http/client.py", line 921, in connect
    self.sock = self._create_connection(
  File "/usr/lib/python3.9/socket.py", line 843, in create_connection
    raise err
  File "/usr/lib/python3.9/socket.py", line 831, in create_connection
    sock.connect(sa)
ConnectionRefusedError: [Errno 111] Connection refused

During handling of the above exception, another exception occurred:

Traceback (most recent call last):
  File "/home/gourav/raspi-app/connection_watchdog.py", line 40, in is_internet_on
    urlopen(str('http://' + self.host_ip), timeout=5)
  File "/usr/lib/python3.9/urllib/request.py", line 214, in urlopen
    return opener.open(url, data, timeout)
  File "/usr/lib/python3.9/urllib/request.py", line 517, in open
    response = self._open(req, data)
  File "/usr/lib/python3.9/urllib/request.py", line 534, in _open
    result = self._call_chain(self.handle_open, protocol, protocol +
  File "/usr/lib/python3.9/urllib/request.py", line 494, in _call_chain
    result = func(*args)
  File "/usr/lib/python3.9/urllib/request.py", line 1375, in http_open
    return self.do_open(http.client.HTTPConnection, req)
  File "/usr/lib/python3.9/urllib/request.py", line 1349, in do_open
    raise URLError(err)
urllib.error.URLError: <urlopen error [Errno 111] Connection refused>
2024-11-21 14:18:28,367 [INFO] Freezing in a spot
2024-11-21 14:18:28,369 [INFO] Connection attempt 12, max_reconnection_attempts 180
2024-11-21 14:18:29,464 [ERROR] ConnectionWatchdog - Network is unreachable: 
Traceback (most recent call last):
  File "/usr/lib/python3.9/urllib/request.py", line 1346, in do_open
    h.request(req.get_method(), req.selector, req.data, headers,
  File "/usr/lib/python3.9/http/client.py", line 1255, in request
    self._send_request(method, url, body, headers, encode_chunked)
  File "/usr/lib/python3.9/http/client.py", line 1301, in _send_request
    self.endheaders(body, encode_chunked=encode_chunked)
  File "/usr/lib/python3.9/http/client.py", line 1250, in endheaders
    self._send_output(message_body, encode_chunked=encode_chunked)
  File "/usr/lib/python3.9/http/client.py", line 1010, in _send_output
    self.send(msg)
  File "/usr/lib/python3.9/http/client.py", line 950, in send
    self.connect()
  File "/usr/lib/python3.9/http/client.py", line 921, in connect
    self.sock = self._create_connection(
  File "/usr/lib/python3.9/socket.py", line 843, in create_connection
    raise err
  File "/usr/lib/python3.9/socket.py", line 831, in create_connection
    sock.connect(sa)
ConnectionRefusedError: [Errno 111] Connection refused

During handling of the above exception, another exception occurred:

Traceback (most recent call last):
  File "/home/gourav/raspi-app/connection_watchdog.py", line 40, in is_internet_on
    urlopen(str('http://' + self.host_ip), timeout=5)
  File "/usr/lib/python3.9/urllib/request.py", line 214, in urlopen
    return opener.open(url, data, timeout)
  File "/usr/lib/python3.9/urllib/request.py", line 517, in open
    response = self._open(req, data)
  File "/usr/lib/python3.9/urllib/request.py", line 534, in _open
    result = self._call_chain(self.handle_open, protocol, protocol +
  File "/usr/lib/python3.9/urllib/request.py", line 494, in _call_chain
    result = func(*args)
  File "/usr/lib/python3.9/urllib/request.py", line 1375, in http_open
    return self.do_open(http.client.HTTPConnection, req)
  File "/usr/lib/python3.9/urllib/request.py", line 1349, in do_open
    raise URLError(err)
urllib.error.URLError: <urlopen error [Errno 111] Connection refused>
2024-11-21 14:18:29,475 [INFO] Freezing in a spot
2024-11-21 14:18:29,477 [INFO] Connection attempt 13, max_reconnection_attempts 180
2024-11-21 14:18:30,575 [ERROR] ConnectionWatchdog - Network is unreachable: 
Traceback (most recent call last):
  File "/usr/lib/python3.9/urllib/request.py", line 1346, in do_open
    h.request(req.get_method(), req.selector, req.data, headers,
  File "/usr/lib/python3.9/http/client.py", line 1255, in request
    self._send_request(method, url, body, headers, encode_chunked)
  File "/usr/lib/python3.9/http/client.py", line 1301, in _send_request
    self.endheaders(body, encode_chunked=encode_chunked)
  File "/usr/lib/python3.9/http/client.py", line 1250, in endheaders
    self._send_output(message_body, encode_chunked=encode_chunked)
  File "/usr/lib/python3.9/http/client.py", line 1010, in _send_output
    self.send(msg)
  File "/usr/lib/python3.9/http/client.py", line 950, in send
    self.connect()
  File "/usr/lib/python3.9/http/client.py", line 921, in connect
    self.sock = self._create_connection(
  File "/usr/lib/python3.9/socket.py", line 843, in create_connection
    raise err
  File "/usr/lib/python3.9/socket.py", line 831, in create_connection
    sock.connect(sa)
ConnectionRefusedError: [Errno 111] Connection refused

During handling of the above exception, another exception occurred:

Traceback (most recent call last):
  File "/home/gourav/raspi-app/connection_watchdog.py", line 40, in is_internet_on
    urlopen(str('http://' + self.host_ip), timeout=5)
  File "/usr/lib/python3.9/urllib/request.py", line 214, in urlopen
    return opener.open(url, data, timeout)
  File "/usr/lib/python3.9/urllib/request.py", line 517, in open
    response = self._open(req, data)
  File "/usr/lib/python3.9/urllib/request.py", line 534, in _open
    result = self._call_chain(self.handle_open, protocol, protocol +
  File "/usr/lib/python3.9/urllib/request.py", line 494, in _call_chain
    result = func(*args)
  File "/usr/lib/python3.9/urllib/request.py", line 1375, in http_open
    return self.do_open(http.client.HTTPConnection, req)
  File "/usr/lib/python3.9/urllib/request.py", line 1349, in do_open
    raise URLError(err)
urllib.error.URLError: <urlopen error [Errno 111] Connection refused>
2024-11-21 14:18:30,577 [INFO] Freezing in a spot
2024-11-21 14:18:30,578 [INFO] Connection attempt 14, max_reconnection_attempts 180
2024-11-21 14:18:31,688 [ERROR] ConnectionWatchdog - Network is unreachable: 
Traceback (most recent call last):
  File "/usr/lib/python3.9/urllib/request.py", line 1346, in do_open
    h.request(req.get_method(), req.selector, req.data, headers,
  File "/usr/lib/python3.9/http/client.py", line 1255, in request
    self._send_request(method, url, body, headers, encode_chunked)
  File "/usr/lib/python3.9/http/client.py", line 1301, in _send_request
    self.endheaders(body, encode_chunked=encode_chunked)
  File "/usr/lib/python3.9/http/client.py", line 1250, in endheaders
    self._send_output(message_body, encode_chunked=encode_chunked)
  File "/usr/lib/python3.9/http/client.py", line 1010, in _send_output
    self.send(msg)
  File "/usr/lib/python3.9/http/client.py", line 950, in send
    self.connect()
  File "/usr/lib/python3.9/http/client.py", line 921, in connect
    self.sock = self._create_connection(
  File "/usr/lib/python3.9/socket.py", line 843, in create_connection
    raise err
  File "/usr/lib/python3.9/socket.py", line 831, in create_connection
    sock.connect(sa)
ConnectionRefusedError: [Errno 111] Connection refused

During handling of the above exception, another exception occurred:

Traceback (most recent call last):
  File "/home/gourav/raspi-app/connection_watchdog.py", line 40, in is_internet_on
    urlopen(str('http://' + self.host_ip), timeout=5)
  File "/usr/lib/python3.9/urllib/request.py", line 214, in urlopen
    return opener.open(url, data, timeout)
  File "/usr/lib/python3.9/urllib/request.py", line 517, in open
    response = self._open(req, data)
  File "/usr/lib/python3.9/urllib/request.py", line 534, in _open
    result = self._call_chain(self.handle_open, protocol, protocol +
  File "/usr/lib/python3.9/urllib/request.py", line 494, in _call_chain
    result = func(*args)
  File "/usr/lib/python3.9/urllib/request.py", line 1375, in http_open
    return self.do_open(http.client.HTTPConnection, req)
  File "/usr/lib/python3.9/urllib/request.py", line 1349, in do_open
    raise URLError(err)
urllib.error.URLError: <urlopen error [Errno 111] Connection refused>
2024-11-21 14:18:31,690 [INFO] Freezing in a spot
2024-11-21 14:18:31,692 [INFO] Connection attempt 15, max_reconnection_attempts 180
2024-11-21 14:18:32,803 [ERROR] ConnectionWatchdog - Network is unreachable: 
Traceback (most recent call last):
  File "/usr/lib/python3.9/urllib/request.py", line 1346, in do_open
    h.request(req.get_method(), req.selector, req.data, headers,
  File "/usr/lib/python3.9/http/client.py", line 1255, in request
    self._send_request(method, url, body, headers, encode_chunked)
  File "/usr/lib/python3.9/http/client.py", line 1301, in _send_request
    self.endheaders(body, encode_chunked=encode_chunked)
  File "/usr/lib/python3.9/http/client.py", line 1250, in endheaders
    self._send_output(message_body, encode_chunked=encode_chunked)
  File "/usr/lib/python3.9/http/client.py", line 1010, in _send_output
    self.send(msg)
  File "/usr/lib/python3.9/http/client.py", line 950, in send
    self.connect()
  File "/usr/lib/python3.9/http/client.py", line 921, in connect
    self.sock = self._create_connection(
  File "/usr/lib/python3.9/socket.py", line 843, in create_connection
    raise err
  File "/usr/lib/python3.9/socket.py", line 831, in create_connection
    sock.connect(sa)
ConnectionRefusedError: [Errno 111] Connection refused

During handling of the above exception, another exception occurred:

Traceback (most recent call last):
  File "/home/gourav/raspi-app/connection_watchdog.py", line 40, in is_internet_on
    urlopen(str('http://' + self.host_ip), timeout=5)
  File "/usr/lib/python3.9/urllib/request.py", line 214, in urlopen
    return opener.open(url, data, timeout)
  File "/usr/lib/python3.9/urllib/request.py", line 517, in open
    response = self._open(req, data)
  File "/usr/lib/python3.9/urllib/request.py", line 534, in _open
    result = self._call_chain(self.handle_open, protocol, protocol +
  File "/usr/lib/python3.9/urllib/request.py", line 494, in _call_chain
    result = func(*args)
  File "/usr/lib/python3.9/urllib/request.py", line 1375, in http_open
    return self.do_open(http.client.HTTPConnection, req)
  File "/usr/lib/python3.9/urllib/request.py", line 1349, in do_open
    raise URLError(err)
urllib.error.URLError: <urlopen error [Errno 111] Connection refused>
2024-11-21 14:18:32,805 [INFO] Freezing in a spot
2024-11-21 14:18:32,807 [INFO] Connection attempt 16, max_reconnection_attempts 180
2024-11-21 14:18:33,893 [ERROR] ConnectionWatchdog - Network is unreachable: 
Traceback (most recent call last):
  File "/usr/lib/python3.9/urllib/request.py", line 1346, in do_open
    h.request(req.get_method(), req.selector, req.data, headers,
  File "/usr/lib/python3.9/http/client.py", line 1255, in request
    self._send_request(method, url, body, headers, encode_chunked)
  File "/usr/lib/python3.9/http/client.py", line 1301, in _send_request
    self.endheaders(body, encode_chunked=encode_chunked)
  File "/usr/lib/python3.9/http/client.py", line 1250, in endheaders
    self._send_output(message_body, encode_chunked=encode_chunked)
  File "/usr/lib/python3.9/http/client.py", line 1010, in _send_output
    self.send(msg)
  File "/usr/lib/python3.9/http/client.py", line 950, in send
    self.connect()
  File "/usr/lib/python3.9/http/client.py", line 921, in connect
    self.sock = self._create_connection(
  File "/usr/lib/python3.9/socket.py", line 843, in create_connection
    raise err
  File "/usr/lib/python3.9/socket.py", line 831, in create_connection
    sock.connect(sa)
ConnectionRefusedError: [Errno 111] Connection refused

During handling of the above exception, another exception occurred:

Traceback (most recent call last):
  File "/home/gourav/raspi-app/connection_watchdog.py", line 40, in is_internet_on
    urlopen(str('http://' + self.host_ip), timeout=5)
  File "/usr/lib/python3.9/urllib/request.py", line 214, in urlopen
    return opener.open(url, data, timeout)
  File "/usr/lib/python3.9/urllib/request.py", line 517, in open
    response = self._open(req, data)
  File "/usr/lib/python3.9/urllib/request.py", line 534, in _open
    result = self._call_chain(self.handle_open, protocol, protocol +
  File "/usr/lib/python3.9/urllib/request.py", line 494, in _call_chain
    result = func(*args)
  File "/usr/lib/python3.9/urllib/request.py", line 1375, in http_open
    return self.do_open(http.client.HTTPConnection, req)
  File "/usr/lib/python3.9/urllib/request.py", line 1349, in do_open
    raise URLError(err)
urllib.error.URLError: <urlopen error [Errno 111] Connection refused>
2024-11-21 14:18:33,896 [INFO] Freezing in a spot
2024-11-21 14:18:33,897 [INFO] Connection attempt 17, max_reconnection_attempts 180
2024-11-21 14:18:34,964 [ERROR] ConnectionWatchdog - Network is unreachable: 
Traceback (most recent call last):
  File "/usr/lib/python3.9/urllib/request.py", line 1346, in do_open
    h.request(req.get_method(), req.selector, req.data, headers,
  File "/usr/lib/python3.9/http/client.py", line 1255, in request
    self._send_request(method, url, body, headers, encode_chunked)
  File "/usr/lib/python3.9/http/client.py", line 1301, in _send_request
    self.endheaders(body, encode_chunked=encode_chunked)
  File "/usr/lib/python3.9/http/client.py", line 1250, in endheaders
    self._send_output(message_body, encode_chunked=encode_chunked)
  File "/usr/lib/python3.9/http/client.py", line 1010, in _send_output
    self.send(msg)
  File "/usr/lib/python3.9/http/client.py", line 950, in send
    self.connect()
  File "/usr/lib/python3.9/http/client.py", line 921, in connect
    self.sock = self._create_connection(
  File "/usr/lib/python3.9/socket.py", line 843, in create_connection
    raise err
  File "/usr/lib/python3.9/socket.py", line 831, in create_connection
    sock.connect(sa)
ConnectionRefusedError: [Errno 111] Connection refused

During handling of the above exception, another exception occurred:

Traceback (most recent call last):
  File "/home/gourav/raspi-app/connection_watchdog.py", line 40, in is_internet_on
    urlopen(str('http://' + self.host_ip), timeout=5)
  File "/usr/lib/python3.9/urllib/request.py", line 214, in urlopen
    return opener.open(url, data, timeout)
  File "/usr/lib/python3.9/urllib/request.py", line 517, in open
    response = self._open(req, data)
  File "/usr/lib/python3.9/urllib/request.py", line 534, in _open
    result = self._call_chain(self.handle_open, protocol, protocol +
  File "/usr/lib/python3.9/urllib/request.py", line 494, in _call_chain
    result = func(*args)
  File "/usr/lib/python3.9/urllib/request.py", line 1375, in http_open
    return self.do_open(http.client.HTTPConnection, req)
  File "/usr/lib/python3.9/urllib/request.py", line 1349, in do_open
    raise URLError(err)
urllib.error.URLError: <urlopen error [Errno 111] Connection refused>
2024-11-21 14:18:34,969 [INFO] Freezing in a spot
2024-11-21 14:18:34,971 [INFO] Connection attempt 18, max_reconnection_attempts 180
2024-11-21 14:18:36,062 [ERROR] ConnectionWatchdog - Network is unreachable: 
Traceback (most recent call last):
  File "/usr/lib/python3.9/urllib/request.py", line 1346, in do_open
    h.request(req.get_method(), req.selector, req.data, headers,
  File "/usr/lib/python3.9/http/client.py", line 1255, in request
    self._send_request(method, url, body, headers, encode_chunked)
  File "/usr/lib/python3.9/http/client.py", line 1301, in _send_request
    self.endheaders(body, encode_chunked=encode_chunked)
  File "/usr/lib/python3.9/http/client.py", line 1250, in endheaders
    self._send_output(message_body, encode_chunked=encode_chunked)
  File "/usr/lib/python3.9/http/client.py", line 1010, in _send_output
    self.send(msg)
  File "/usr/lib/python3.9/http/client.py", line 950, in send
    self.connect()
  File "/usr/lib/python3.9/http/client.py", line 921, in connect
    self.sock = self._create_connection(
  File "/usr/lib/python3.9/socket.py", line 843, in create_connection
    raise err
  File "/usr/lib/python3.9/socket.py", line 831, in create_connection
    sock.connect(sa)
ConnectionRefusedError: [Errno 111] Connection refused

During handling of the above exception, another exception occurred:

Traceback (most recent call last):
  File "/home/gourav/raspi-app/connection_watchdog.py", line 40, in is_internet_on
    urlopen(str('http://' + self.host_ip), timeout=5)
  File "/usr/lib/python3.9/urllib/request.py", line 214, in urlopen
    return opener.open(url, data, timeout)
  File "/usr/lib/python3.9/urllib/request.py", line 517, in open
    response = self._open(req, data)
  File "/usr/lib/python3.9/urllib/request.py", line 534, in _open
    result = self._call_chain(self.handle_open, protocol, protocol +
  File "/usr/lib/python3.9/urllib/request.py", line 494, in _call_chain
    result = func(*args)
  File "/usr/lib/python3.9/urllib/request.py", line 1375, in http_open
    return self.do_open(http.client.HTTPConnection, req)
  File "/usr/lib/python3.9/urllib/request.py", line 1349, in do_open
    raise URLError(err)
urllib.error.URLError: <urlopen error [Errno 111] Connection refused>
2024-11-21 14:18:36,065 [INFO] Freezing in a spot
2024-11-21 14:18:36,066 [INFO] Connection attempt 19, max_reconnection_attempts 180
2024-11-21 14:18:37,123 [ERROR] ConnectionWatchdog - Network is unreachable: 
Traceback (most recent call last):
  File "/usr/lib/python3.9/urllib/request.py", line 1346, in do_open
    h.request(req.get_method(), req.selector, req.data, headers,
  File "/usr/lib/python3.9/http/client.py", line 1255, in request
    self._send_request(method, url, body, headers, encode_chunked)
  File "/usr/lib/python3.9/http/client.py", line 1301, in _send_request
    self.endheaders(body, encode_chunked=encode_chunked)
  File "/usr/lib/python3.9/http/client.py", line 1250, in endheaders
    self._send_output(message_body, encode_chunked=encode_chunked)
  File "/usr/lib/python3.9/http/client.py", line 1010, in _send_output
    self.send(msg)
  File "/usr/lib/python3.9/http/client.py", line 950, in send
    self.connect()
  File "/usr/lib/python3.9/http/client.py", line 921, in connect
    self.sock = self._create_connection(
  File "/usr/lib/python3.9/socket.py", line 843, in create_connection
    raise err
  File "/usr/lib/python3.9/socket.py", line 831, in create_connection
    sock.connect(sa)
ConnectionRefusedError: [Errno 111] Connection refused

During handling of the above exception, another exception occurred:

Traceback (most recent call last):
  File "/home/gourav/raspi-app/connection_watchdog.py", line 40, in is_internet_on
    urlopen(str('http://' + self.host_ip), timeout=5)
  File "/usr/lib/python3.9/urllib/request.py", line 214, in urlopen
    return opener.open(url, data, timeout)
  File "/usr/lib/python3.9/urllib/request.py", line 517, in open
    response = self._open(req, data)
  File "/usr/lib/python3.9/urllib/request.py", line 534, in _open
    result = self._call_chain(self.handle_open, protocol, protocol +
  File "/usr/lib/python3.9/urllib/request.py", line 494, in _call_chain
    result = func(*args)
  File "/usr/lib/python3.9/urllib/request.py", line 1375, in http_open
    return self.do_open(http.client.HTTPConnection, req)
  File "/usr/lib/python3.9/urllib/request.py", line 1349, in do_open
    raise URLError(err)
urllib.error.URLError: <urlopen error [Errno 111] Connection refused>
2024-11-21 14:18:37,125 [INFO] Freezing in a spot
2024-11-21 14:18:37,127 [INFO] Connection attempt 20, max_reconnection_attempts 180
2024-11-21 14:18:38,236 [ERROR] ConnectionWatchdog - Network is unreachable: 
Traceback (most recent call last):
  File "/usr/lib/python3.9/urllib/request.py", line 1346, in do_open
    h.request(req.get_method(), req.selector, req.data, headers,
  File "/usr/lib/python3.9/http/client.py", line 1255, in request
    self._send_request(method, url, body, headers, encode_chunked)
  File "/usr/lib/python3.9/http/client.py", line 1301, in _send_request
    self.endheaders(body, encode_chunked=encode_chunked)
  File "/usr/lib/python3.9/http/client.py", line 1250, in endheaders
    self._send_output(message_body, encode_chunked=encode_chunked)
  File "/usr/lib/python3.9/http/client.py", line 1010, in _send_output
    self.send(msg)
  File "/usr/lib/python3.9/http/client.py", line 950, in send
    self.connect()
  File "/usr/lib/python3.9/http/client.py", line 921, in connect
    self.sock = self._create_connection(
  File "/usr/lib/python3.9/socket.py", line 843, in create_connection
    raise err
  File "/usr/lib/python3.9/socket.py", line 831, in create_connection
    sock.connect(sa)
ConnectionRefusedError: [Errno 111] Connection refused

During handling of the above exception, another exception occurred:

Traceback (most recent call last):
  File "/home/gourav/raspi-app/connection_watchdog.py", line 40, in is_internet_on
    urlopen(str('http://' + self.host_ip), timeout=5)
  File "/usr/lib/python3.9/urllib/request.py", line 214, in urlopen
    return opener.open(url, data, timeout)
  File "/usr/lib/python3.9/urllib/request.py", line 517, in open
    response = self._open(req, data)
  File "/usr/lib/python3.9/urllib/request.py", line 534, in _open
    result = self._call_chain(self.handle_open, protocol, protocol +
  File "/usr/lib/python3.9/urllib/request.py", line 494, in _call_chain
    result = func(*args)
  File "/usr/lib/python3.9/urllib/request.py", line 1375, in http_open
    return self.do_open(http.client.HTTPConnection, req)
  File "/usr/lib/python3.9/urllib/request.py", line 1349, in do_open
    raise URLError(err)
urllib.error.URLError: <urlopen error [Errno 111] Connection refused>
2024-11-21 14:18:38,241 [INFO] Freezing in a spot
2024-11-21 14:18:38,243 [INFO] Connection attempt 21, max_reconnection_attempts 180
2024-11-21 14:18:39,293 [ERROR] ConnectionWatchdog - Network is unreachable: 
Traceback (most recent call last):
  File "/usr/lib/python3.9/urllib/request.py", line 1346, in do_open
    h.request(req.get_method(), req.selector, req.data, headers,
  File "/usr/lib/python3.9/http/client.py", line 1255, in request
    self._send_request(method, url, body, headers, encode_chunked)
  File "/usr/lib/python3.9/http/client.py", line 1301, in _send_request
    self.endheaders(body, encode_chunked=encode_chunked)
  File "/usr/lib/python3.9/http/client.py", line 1250, in endheaders
    self._send_output(message_body, encode_chunked=encode_chunked)
  File "/usr/lib/python3.9/http/client.py", line 1010, in _send_output
    self.send(msg)
  File "/usr/lib/python3.9/http/client.py", line 950, in send
    self.connect()
  File "/usr/lib/python3.9/http/client.py", line 921, in connect
    self.sock = self._create_connection(
  File "/usr/lib/python3.9/socket.py", line 843, in create_connection
    raise err
  File "/usr/lib/python3.9/socket.py", line 831, in create_connection
    sock.connect(sa)
ConnectionRefusedError: [Errno 111] Connection refused

During handling of the above exception, another exception occurred:

Traceback (most recent call last):
  File "/home/gourav/raspi-app/connection_watchdog.py", line 40, in is_internet_on
    urlopen(str('http://' + self.host_ip), timeout=5)
  File "/usr/lib/python3.9/urllib/request.py", line 214, in urlopen
    return opener.open(url, data, timeout)
  File "/usr/lib/python3.9/urllib/request.py", line 517, in open
    response = self._open(req, data)
  File "/usr/lib/python3.9/urllib/request.py", line 534, in _open
    result = self._call_chain(self.handle_open, protocol, protocol +
  File "/usr/lib/python3.9/urllib/request.py", line 494, in _call_chain
    result = func(*args)
  File "/usr/lib/python3.9/urllib/request.py", line 1375, in http_open
    return self.do_open(http.client.HTTPConnection, req)
  File "/usr/lib/python3.9/urllib/request.py", line 1349, in do_open
    raise URLError(err)
urllib.error.URLError: <urlopen error [Errno 111] Connection refused>
2024-11-21 14:18:39,298 [INFO] Freezing in a spot
2024-11-21 14:18:39,300 [INFO] Connection attempt 22, max_reconnection_attempts 180
2024-11-21 14:18:40,412 [ERROR] ConnectionWatchdog - Network is unreachable: 
Traceback (most recent call last):
  File "/usr/lib/python3.9/urllib/request.py", line 1346, in do_open
    h.request(req.get_method(), req.selector, req.data, headers,
  File "/usr/lib/python3.9/http/client.py", line 1255, in request
    self._send_request(method, url, body, headers, encode_chunked)
  File "/usr/lib/python3.9/http/client.py", line 1301, in _send_request
    self.endheaders(body, encode_chunked=encode_chunked)
  File "/usr/lib/python3.9/http/client.py", line 1250, in endheaders
    self._send_output(message_body, encode_chunked=encode_chunked)
  File "/usr/lib/python3.9/http/client.py", line 1010, in _send_output
    self.send(msg)
  File "/usr/lib/python3.9/http/client.py", line 950, in send
    self.connect()
  File "/usr/lib/python3.9/http/client.py", line 921, in connect
    self.sock = self._create_connection(
  File "/usr/lib/python3.9/socket.py", line 843, in create_connection
    raise err
  File "/usr/lib/python3.9/socket.py", line 831, in create_connection
    sock.connect(sa)
ConnectionRefusedError: [Errno 111] Connection refused

During handling of the above exception, another exception occurred:

Traceback (most recent call last):
  File "/home/gourav/raspi-app/connection_watchdog.py", line 40, in is_internet_on
    urlopen(str('http://' + self.host_ip), timeout=5)
  File "/usr/lib/python3.9/urllib/request.py", line 214, in urlopen
    return opener.open(url, data, timeout)
  File "/usr/lib/python3.9/urllib/request.py", line 517, in open
    response = self._open(req, data)
  File "/usr/lib/python3.9/urllib/request.py", line 534, in _open
    result = self._call_chain(self.handle_open, protocol, protocol +
  File "/usr/lib/python3.9/urllib/request.py", line 494, in _call_chain
    result = func(*args)
  File "/usr/lib/python3.9/urllib/request.py", line 1375, in http_open
    return self.do_open(http.client.HTTPConnection, req)
  File "/usr/lib/python3.9/urllib/request.py", line 1349, in do_open
    raise URLError(err)
urllib.error.URLError: <urlopen error [Errno 111] Connection refused>
2024-11-21 14:18:40,427 [INFO] Freezing in a spot
2024-11-21 14:18:40,428 [INFO] Connection attempt 23, max_reconnection_attempts 180
2024-11-21 14:18:41,533 [ERROR] ConnectionWatchdog - Network is unreachable: 
Traceback (most recent call last):
  File "/usr/lib/python3.9/urllib/request.py", line 1346, in do_open
    h.request(req.get_method(), req.selector, req.data, headers,
  File "/usr/lib/python3.9/http/client.py", line 1255, in request
    self._send_request(method, url, body, headers, encode_chunked)
  File "/usr/lib/python3.9/http/client.py", line 1301, in _send_request
    self.endheaders(body, encode_chunked=encode_chunked)
  File "/usr/lib/python3.9/http/client.py", line 1250, in endheaders
    self._send_output(message_body, encode_chunked=encode_chunked)
  File "/usr/lib/python3.9/http/client.py", line 1010, in _send_output
    self.send(msg)
  File "/usr/lib/python3.9/http/client.py", line 950, in send
    self.connect()
  File "/usr/lib/python3.9/http/client.py", line 921, in connect
    self.sock = self._create_connection(
  File "/usr/lib/python3.9/socket.py", line 843, in create_connection
    raise err
  File "/usr/lib/python3.9/socket.py", line 831, in create_connection
    sock.connect(sa)
ConnectionRefusedError: [Errno 111] Connection refused

During handling of the above exception, another exception occurred:

Traceback (most recent call last):
  File "/home/gourav/raspi-app/connection_watchdog.py", line 40, in is_internet_on
    urlopen(str('http://' + self.host_ip), timeout=5)
  File "/usr/lib/python3.9/urllib/request.py", line 214, in urlopen
    return opener.open(url, data, timeout)
  File "/usr/lib/python3.9/urllib/request.py", line 517, in open
    response = self._open(req, data)
  File "/usr/lib/python3.9/urllib/request.py", line 534, in _open
    result = self._call_chain(self.handle_open, protocol, protocol +
  File "/usr/lib/python3.9/urllib/request.py", line 494, in _call_chain
    result = func(*args)
  File "/usr/lib/python3.9/urllib/request.py", line 1375, in http_open
    return self.do_open(http.client.HTTPConnection, req)
  File "/usr/lib/python3.9/urllib/request.py", line 1349, in do_open
    raise URLError(err)
urllib.error.URLError: <urlopen error [Errno 111] Connection refused>
2024-11-21 14:18:41,538 [INFO] Freezing in a spot
2024-11-21 14:18:41,539 [INFO] Connection attempt 24, max_reconnection_attempts 180
2024-11-21 14:18:42,633 [ERROR] ConnectionWatchdog - Network is unreachable: 
Traceback (most recent call last):
  File "/usr/lib/python3.9/urllib/request.py", line 1346, in do_open
    h.request(req.get_method(), req.selector, req.data, headers,
  File "/usr/lib/python3.9/http/client.py", line 1255, in request
    self._send_request(method, url, body, headers, encode_chunked)
  File "/usr/lib/python3.9/http/client.py", line 1301, in _send_request
    self.endheaders(body, encode_chunked=encode_chunked)
  File "/usr/lib/python3.9/http/client.py", line 1250, in endheaders
    self._send_output(message_body, encode_chunked=encode_chunked)
  File "/usr/lib/python3.9/http/client.py", line 1010, in _send_output
    self.send(msg)
  File "/usr/lib/python3.9/http/client.py", line 950, in send
    self.connect()
  File "/usr/lib/python3.9/http/client.py", line 921, in connect
    self.sock = self._create_connection(
  File "/usr/lib/python3.9/socket.py", line 843, in create_connection
    raise err
  File "/usr/lib/python3.9/socket.py", line 831, in create_connection
    sock.connect(sa)
ConnectionRefusedError: [Errno 111] Connection refused

During handling of the above exception, another exception occurred:

Traceback (most recent call last):
  File "/home/gourav/raspi-app/connection_watchdog.py", line 40, in is_internet_on
    urlopen(str('http://' + self.host_ip), timeout=5)
  File "/usr/lib/python3.9/urllib/request.py", line 214, in urlopen
    return opener.open(url, data, timeout)
  File "/usr/lib/python3.9/urllib/request.py", line 517, in open
    response = self._open(req, data)
  File "/usr/lib/python3.9/urllib/request.py", line 534, in _open
    result = self._call_chain(self.handle_open, protocol, protocol +
  File "/usr/lib/python3.9/urllib/request.py", line 494, in _call_chain
    result = func(*args)
  File "/usr/lib/python3.9/urllib/request.py", line 1375, in http_open
    return self.do_open(http.client.HTTPConnection, req)
  File "/usr/lib/python3.9/urllib/request.py", line 1349, in do_open
    raise URLError(err)
urllib.error.URLError: <urlopen error [Errno 111] Connection refused>
2024-11-21 14:18:42,637 [INFO] Freezing in a spot
2024-11-21 14:18:42,638 [INFO] Connection attempt 25, max_reconnection_attempts 180
2024-11-21 14:18:43,720 [ERROR] ConnectionWatchdog - Network is unreachable: 
Traceback (most recent call last):
  File "/usr/lib/python3.9/urllib/request.py", line 1346, in do_open
    h.request(req.get_method(), req.selector, req.data, headers,
  File "/usr/lib/python3.9/http/client.py", line 1255, in request
    self._send_request(method, url, body, headers, encode_chunked)
  File "/usr/lib/python3.9/http/client.py", line 1301, in _send_request
    self.endheaders(body, encode_chunked=encode_chunked)
  File "/usr/lib/python3.9/http/client.py", line 1250, in endheaders
    self._send_output(message_body, encode_chunked=encode_chunked)
  File "/usr/lib/python3.9/http/client.py", line 1010, in _send_output
    self.send(msg)
  File "/usr/lib/python3.9/http/client.py", line 950, in send
    self.connect()
  File "/usr/lib/python3.9/http/client.py", line 921, in connect
    self.sock = self._create_connection(
  File "/usr/lib/python3.9/socket.py", line 843, in create_connection
    raise err
  File "/usr/lib/python3.9/socket.py", line 831, in create_connection
    sock.connect(sa)
ConnectionRefusedError: [Errno 111] Connection refused

During handling of the above exception, another exception occurred:

Traceback (most recent call last):
  File "/home/gourav/raspi-app/connection_watchdog.py", line 40, in is_internet_on
    urlopen(str('http://' + self.host_ip), timeout=5)
  File "/usr/lib/python3.9/urllib/request.py", line 214, in urlopen
    return opener.open(url, data, timeout)
  File "/usr/lib/python3.9/urllib/request.py", line 517, in open
    response = self._open(req, data)
  File "/usr/lib/python3.9/urllib/request.py", line 534, in _open
    result = self._call_chain(self.handle_open, protocol, protocol +
  File "/usr/lib/python3.9/urllib/request.py", line 494, in _call_chain
    result = func(*args)
  File "/usr/lib/python3.9/urllib/request.py", line 1375, in http_open
    return self.do_open(http.client.HTTPConnection, req)
  File "/usr/lib/python3.9/urllib/request.py", line 1349, in do_open
    raise URLError(err)
urllib.error.URLError: <urlopen error [Errno 111] Connection refused>
2024-11-21 14:18:43,725 [INFO] Freezing in a spot
2024-11-21 14:18:43,726 [INFO] Connection attempt 26, max_reconnection_attempts 180
2024-11-21 14:18:44,822 [ERROR] ConnectionWatchdog - Network is unreachable: 
Traceback (most recent call last):
  File "/usr/lib/python3.9/urllib/request.py", line 1346, in do_open
    h.request(req.get_method(), req.selector, req.data, headers,
  File "/usr/lib/python3.9/http/client.py", line 1255, in request
    self._send_request(method, url, body, headers, encode_chunked)
  File "/usr/lib/python3.9/http/client.py", line 1301, in _send_request
    self.endheaders(body, encode_chunked=encode_chunked)
  File "/usr/lib/python3.9/http/client.py", line 1250, in endheaders
    self._send_output(message_body, encode_chunked=encode_chunked)
  File "/usr/lib/python3.9/http/client.py", line 1010, in _send_output
    self.send(msg)
  File "/usr/lib/python3.9/http/client.py", line 950, in send
    self.connect()
  File "/usr/lib/python3.9/http/client.py", line 921, in connect
    self.sock = self._create_connection(
  File "/usr/lib/python3.9/socket.py", line 843, in create_connection
    raise err
  File "/usr/lib/python3.9/socket.py", line 831, in create_connection
    sock.connect(sa)
ConnectionRefusedError: [Errno 111] Connection refused

During handling of the above exception, another exception occurred:

Traceback (most recent call last):
  File "/home/gourav/raspi-app/connection_watchdog.py", line 40, in is_internet_on
    urlopen(str('http://' + self.host_ip), timeout=5)
  File "/usr/lib/python3.9/urllib/request.py", line 214, in urlopen
    return opener.open(url, data, timeout)
  File "/usr/lib/python3.9/urllib/request.py", line 517, in open
    response = self._open(req, data)
  File "/usr/lib/python3.9/urllib/request.py", line 534, in _open
    result = self._call_chain(self.handle_open, protocol, protocol +
  File "/usr/lib/python3.9/urllib/request.py", line 494, in _call_chain
    result = func(*args)
  File "/usr/lib/python3.9/urllib/request.py", line 1375, in http_open
    return self.do_open(http.client.HTTPConnection, req)
  File "/usr/lib/python3.9/urllib/request.py", line 1349, in do_open
    raise URLError(err)
urllib.error.URLError: <urlopen error [Errno 111] Connection refused>
2024-11-21 14:18:44,826 [INFO] Freezing in a spot
2024-11-21 14:18:44,827 [INFO] Connection attempt 27, max_reconnection_attempts 180
2024-11-21 14:18:45,883 [ERROR] ConnectionWatchdog - Network is unreachable: 
Traceback (most recent call last):
  File "/usr/lib/python3.9/urllib/request.py", line 1346, in do_open
    h.request(req.get_method(), req.selector, req.data, headers,
  File "/usr/lib/python3.9/http/client.py", line 1255, in request
    self._send_request(method, url, body, headers, encode_chunked)
  File "/usr/lib/python3.9/http/client.py", line 1301, in _send_request
    self.endheaders(body, encode_chunked=encode_chunked)
  File "/usr/lib/python3.9/http/client.py", line 1250, in endheaders
    self._send_output(message_body, encode_chunked=encode_chunked)
  File "/usr/lib/python3.9/http/client.py", line 1010, in _send_output
    self.send(msg)
  File "/usr/lib/python3.9/http/client.py", line 950, in send
    self.connect()
  File "/usr/lib/python3.9/http/client.py", line 921, in connect
    self.sock = self._create_connection(
  File "/usr/lib/python3.9/socket.py", line 843, in create_connection
    raise err
  File "/usr/lib/python3.9/socket.py", line 831, in create_connection
    sock.connect(sa)
ConnectionRefusedError: [Errno 111] Connection refused

During handling of the above exception, another exception occurred:

Traceback (most recent call last):
  File "/home/gourav/raspi-app/connection_watchdog.py", line 40, in is_internet_on
    urlopen(str('http://' + self.host_ip), timeout=5)
  File "/usr/lib/python3.9/urllib/request.py", line 214, in urlopen
    return opener.open(url, data, timeout)
  File "/usr/lib/python3.9/urllib/request.py", line 517, in open
    response = self._open(req, data)
  File "/usr/lib/python3.9/urllib/request.py", line 534, in _open
    result = self._call_chain(self.handle_open, protocol, protocol +
  File "/usr/lib/python3.9/urllib/request.py", line 494, in _call_chain
    result = func(*args)
  File "/usr/lib/python3.9/urllib/request.py", line 1375, in http_open
    return self.do_open(http.client.HTTPConnection, req)
  File "/usr/lib/python3.9/urllib/request.py", line 1349, in do_open
    raise URLError(err)
urllib.error.URLError: <urlopen error [Errno 111] Connection refused>
2024-11-21 14:18:45,887 [INFO] Freezing in a spot
2024-11-21 14:18:45,888 [INFO] Connection attempt 28, max_reconnection_attempts 180
2024-11-21 14:18:46,711 [INFO] EKF3 IMU0 is using GPS
2024-11-21 14:18:46,712 [INFO] EKF3 IMU1 is using GPS
2024-11-21 14:18:46,952 [ERROR] ConnectionWatchdog - Network is unreachable: 
Traceback (most recent call last):
  File "/usr/lib/python3.9/urllib/request.py", line 1346, in do_open
    h.request(req.get_method(), req.selector, req.data, headers,
  File "/usr/lib/python3.9/http/client.py", line 1255, in request
    self._send_request(method, url, body, headers, encode_chunked)
  File "/usr/lib/python3.9/http/client.py", line 1301, in _send_request
    self.endheaders(body, encode_chunked=encode_chunked)
  File "/usr/lib/python3.9/http/client.py", line 1250, in endheaders
    self._send_output(message_body, encode_chunked=encode_chunked)
  File "/usr/lib/python3.9/http/client.py", line 1010, in _send_output
    self.send(msg)
  File "/usr/lib/python3.9/http/client.py", line 950, in send
    self.connect()
  File "/usr/lib/python3.9/http/client.py", line 921, in connect
    self.sock = self._create_connection(
  File "/usr/lib/python3.9/socket.py", line 843, in create_connection
    raise err
  File "/usr/lib/python3.9/socket.py", line 831, in create_connection
    sock.connect(sa)
ConnectionRefusedError: [Errno 111] Connection refused

During handling of the above exception, another exception occurred:

Traceback (most recent call last):
  File "/home/gourav/raspi-app/connection_watchdog.py", line 40, in is_internet_on
    urlopen(str('http://' + self.host_ip), timeout=5)
  File "/usr/lib/python3.9/urllib/request.py", line 214, in urlopen
    return opener.open(url, data, timeout)
  File "/usr/lib/python3.9/urllib/request.py", line 517, in open
    response = self._open(req, data)
  File "/usr/lib/python3.9/urllib/request.py", line 534, in _open
    result = self._call_chain(self.handle_open, protocol, protocol +
  File "/usr/lib/python3.9/urllib/request.py", line 494, in _call_chain
    result = func(*args)
  File "/usr/lib/python3.9/urllib/request.py", line 1375, in http_open
    return self.do_open(http.client.HTTPConnection, req)
  File "/usr/lib/python3.9/urllib/request.py", line 1349, in do_open
    raise URLError(err)
urllib.error.URLError: <urlopen error [Errno 111] Connection refused>
2024-11-21 14:18:46,956 [INFO] Freezing in a spot
2024-11-21 14:18:46,957 [INFO] Connection attempt 29, max_reconnection_attempts 180
2024-11-21 14:18:48,042 [ERROR] ConnectionWatchdog - Network is unreachable: 
Traceback (most recent call last):
  File "/usr/lib/python3.9/urllib/request.py", line 1346, in do_open
    h.request(req.get_method(), req.selector, req.data, headers,
  File "/usr/lib/python3.9/http/client.py", line 1255, in request
    self._send_request(method, url, body, headers, encode_chunked)
  File "/usr/lib/python3.9/http/client.py", line 1301, in _send_request
    self.endheaders(body, encode_chunked=encode_chunked)
  File "/usr/lib/python3.9/http/client.py", line 1250, in endheaders
    self._send_output(message_body, encode_chunked=encode_chunked)
  File "/usr/lib/python3.9/http/client.py", line 1010, in _send_output
    self.send(msg)
  File "/usr/lib/python3.9/http/client.py", line 950, in send
    self.connect()
  File "/usr/lib/python3.9/http/client.py", line 921, in connect
    self.sock = self._create_connection(
  File "/usr/lib/python3.9/socket.py", line 843, in create_connection
    raise err
  File "/usr/lib/python3.9/socket.py", line 831, in create_connection
    sock.connect(sa)
ConnectionRefusedError: [Errno 111] Connection refused

During handling of the above exception, another exception occurred:

Traceback (most recent call last):
  File "/home/gourav/raspi-app/connection_watchdog.py", line 40, in is_internet_on
    urlopen(str('http://' + self.host_ip), timeout=5)
  File "/usr/lib/python3.9/urllib/request.py", line 214, in urlopen
    return opener.open(url, data, timeout)
  File "/usr/lib/python3.9/urllib/request.py", line 517, in open
    response = self._open(req, data)
  File "/usr/lib/python3.9/urllib/request.py", line 534, in _open
    result = self._call_chain(self.handle_open, protocol, protocol +
  File "/usr/lib/python3.9/urllib/request.py", line 494, in _call_chain
    result = func(*args)
  File "/usr/lib/python3.9/urllib/request.py", line 1375, in http_open
    return self.do_open(http.client.HTTPConnection, req)
  File "/usr/lib/python3.9/urllib/request.py", line 1349, in do_open
    raise URLError(err)
urllib.error.URLError: <urlopen error [Errno 111] Connection refused>
2024-11-21 14:18:48,046 [INFO] Freezing in a spot
2024-11-21 14:18:48,047 [INFO] Connection attempt 30, max_reconnection_attempts 180
2024-11-21 14:18:49,144 [ERROR] ConnectionWatchdog - Network is unreachable: 
Traceback (most recent call last):
  File "/usr/lib/python3.9/urllib/request.py", line 1346, in do_open
    h.request(req.get_method(), req.selector, req.data, headers,
  File "/usr/lib/python3.9/http/client.py", line 1255, in request
    self._send_request(method, url, body, headers, encode_chunked)
  File "/usr/lib/python3.9/http/client.py", line 1301, in _send_request
    self.endheaders(body, encode_chunked=encode_chunked)
  File "/usr/lib/python3.9/http/client.py", line 1250, in endheaders
    self._send_output(message_body, encode_chunked=encode_chunked)
  File "/usr/lib/python3.9/http/client.py", line 1010, in _send_output
    self.send(msg)
  File "/usr/lib/python3.9/http/client.py", line 950, in send
    self.connect()
  File "/usr/lib/python3.9/http/client.py", line 921, in connect
    self.sock = self._create_connection(
  File "/usr/lib/python3.9/socket.py", line 843, in create_connection
    raise err
  File "/usr/lib/python3.9/socket.py", line 831, in create_connection
    sock.connect(sa)
ConnectionRefusedError: [Errno 111] Connection refused

During handling of the above exception, another exception occurred:

Traceback (most recent call last):
  File "/home/gourav/raspi-app/connection_watchdog.py", line 40, in is_internet_on
    urlopen(str('http://' + self.host_ip), timeout=5)
  File "/usr/lib/python3.9/urllib/request.py", line 214, in urlopen
    return opener.open(url, data, timeout)
  File "/usr/lib/python3.9/urllib/request.py", line 517, in open
    response = self._open(req, data)
  File "/usr/lib/python3.9/urllib/request.py", line 534, in _open
    result = self._call_chain(self.handle_open, protocol, protocol +
  File "/usr/lib/python3.9/urllib/request.py", line 494, in _call_chain
    result = func(*args)
  File "/usr/lib/python3.9/urllib/request.py", line 1375, in http_open
    return self.do_open(http.client.HTTPConnection, req)
  File "/usr/lib/python3.9/urllib/request.py", line 1349, in do_open
    raise URLError(err)
urllib.error.URLError: <urlopen error [Errno 111] Connection refused>
2024-11-21 14:18:49,149 [INFO] Freezing in a spot
2024-11-21 14:18:49,151 [INFO] Connection attempt 31, max_reconnection_attempts 180
2024-11-21 14:18:50,223 [ERROR] ConnectionWatchdog - Network is unreachable: 
Traceback (most recent call last):
  File "/usr/lib/python3.9/urllib/request.py", line 1346, in do_open
    h.request(req.get_method(), req.selector, req.data, headers,
  File "/usr/lib/python3.9/http/client.py", line 1255, in request
    self._send_request(method, url, body, headers, encode_chunked)
  File "/usr/lib/python3.9/http/client.py", line 1301, in _send_request
    self.endheaders(body, encode_chunked=encode_chunked)
  File "/usr/lib/python3.9/http/client.py", line 1250, in endheaders
    self._send_output(message_body, encode_chunked=encode_chunked)
  File "/usr/lib/python3.9/http/client.py", line 1010, in _send_output
    self.send(msg)
  File "/usr/lib/python3.9/http/client.py", line 950, in send
    self.connect()
  File "/usr/lib/python3.9/http/client.py", line 921, in connect
    self.sock = self._create_connection(
  File "/usr/lib/python3.9/socket.py", line 843, in create_connection
    raise err
  File "/usr/lib/python3.9/socket.py", line 831, in create_connection
    sock.connect(sa)
ConnectionRefusedError: [Errno 111] Connection refused

During handling of the above exception, another exception occurred:

Traceback (most recent call last):
  File "/home/gourav/raspi-app/connection_watchdog.py", line 40, in is_internet_on
    urlopen(str('http://' + self.host_ip), timeout=5)
  File "/usr/lib/python3.9/urllib/request.py", line 214, in urlopen
    return opener.open(url, data, timeout)
  File "/usr/lib/python3.9/urllib/request.py", line 517, in open
    response = self._open(req, data)
  File "/usr/lib/python3.9/urllib/request.py", line 534, in _open
    result = self._call_chain(self.handle_open, protocol, protocol +
  File "/usr/lib/python3.9/urllib/request.py", line 494, in _call_chain
    result = func(*args)
  File "/usr/lib/python3.9/urllib/request.py", line 1375, in http_open
    return self.do_open(http.client.HTTPConnection, req)
  File "/usr/lib/python3.9/urllib/request.py", line 1349, in do_open
    raise URLError(err)
urllib.error.URLError: <urlopen error [Errno 111] Connection refused>
2024-11-21 14:18:50,227 [INFO] Freezing in a spot
2024-11-21 14:18:50,229 [INFO] Connection attempt 32, max_reconnection_attempts 180
2024-11-21 14:18:51,342 [ERROR] ConnectionWatchdog - Network is unreachable: 
Traceback (most recent call last):
  File "/usr/lib/python3.9/urllib/request.py", line 1346, in do_open
    h.request(req.get_method(), req.selector, req.data, headers,
  File "/usr/lib/python3.9/http/client.py", line 1255, in request
    self._send_request(method, url, body, headers, encode_chunked)
  File "/usr/lib/python3.9/http/client.py", line 1301, in _send_request
    self.endheaders(body, encode_chunked=encode_chunked)
  File "/usr/lib/python3.9/http/client.py", line 1250, in endheaders
    self._send_output(message_body, encode_chunked=encode_chunked)
  File "/usr/lib/python3.9/http/client.py", line 1010, in _send_output
    self.send(msg)
  File "/usr/lib/python3.9/http/client.py", line 950, in send
    self.connect()
  File "/usr/lib/python3.9/http/client.py", line 921, in connect
    self.sock = self._create_connection(
  File "/usr/lib/python3.9/socket.py", line 843, in create_connection
    raise err
  File "/usr/lib/python3.9/socket.py", line 831, in create_connection
    sock.connect(sa)
ConnectionRefusedError: [Errno 111] Connection refused

During handling of the above exception, another exception occurred:

Traceback (most recent call last):
  File "/home/gourav/raspi-app/connection_watchdog.py", line 40, in is_internet_on
    urlopen(str('http://' + self.host_ip), timeout=5)
  File "/usr/lib/python3.9/urllib/request.py", line 214, in urlopen
    return opener.open(url, data, timeout)
  File "/usr/lib/python3.9/urllib/request.py", line 517, in open
    response = self._open(req, data)
  File "/usr/lib/python3.9/urllib/request.py", line 534, in _open
    result = self._call_chain(self.handle_open, protocol, protocol +
  File "/usr/lib/python3.9/urllib/request.py", line 494, in _call_chain
    result = func(*args)
  File "/usr/lib/python3.9/urllib/request.py", line 1375, in http_open
    return self.do_open(http.client.HTTPConnection, req)
  File "/usr/lib/python3.9/urllib/request.py", line 1349, in do_open
    raise URLError(err)
urllib.error.URLError: <urlopen error [Errno 111] Connection refused>
2024-11-21 14:18:51,353 [INFO] Freezing in a spot
2024-11-21 14:18:51,355 [INFO] Connection attempt 33, max_reconnection_attempts 180
2024-11-21 14:18:52,461 [ERROR] ConnectionWatchdog - Network is unreachable: 
Traceback (most recent call last):
  File "/usr/lib/python3.9/urllib/request.py", line 1346, in do_open
    h.request(req.get_method(), req.selector, req.data, headers,
  File "/usr/lib/python3.9/http/client.py", line 1255, in request
    self._send_request(method, url, body, headers, encode_chunked)
  File "/usr/lib/python3.9/http/client.py", line 1301, in _send_request
    self.endheaders(body, encode_chunked=encode_chunked)
  File "/usr/lib/python3.9/http/client.py", line 1250, in endheaders
    self._send_output(message_body, encode_chunked=encode_chunked)
  File "/usr/lib/python3.9/http/client.py", line 1010, in _send_output
    self.send(msg)
  File "/usr/lib/python3.9/http/client.py", line 950, in send
    self.connect()
  File "/usr/lib/python3.9/http/client.py", line 921, in connect
    self.sock = self._create_connection(
  File "/usr/lib/python3.9/socket.py", line 843, in create_connection
    raise err
  File "/usr/lib/python3.9/socket.py", line 831, in create_connection
    sock.connect(sa)
ConnectionRefusedError: [Errno 111] Connection refused

During handling of the above exception, another exception occurred:

Traceback (most recent call last):
  File "/home/gourav/raspi-app/connection_watchdog.py", line 40, in is_internet_on
    urlopen(str('http://' + self.host_ip), timeout=5)
  File "/usr/lib/python3.9/urllib/request.py", line 214, in urlopen
    return opener.open(url, data, timeout)
  File "/usr/lib/python3.9/urllib/request.py", line 517, in open
    response = self._open(req, data)
  File "/usr/lib/python3.9/urllib/request.py", line 534, in _open
    result = self._call_chain(self.handle_open, protocol, protocol +
  File "/usr/lib/python3.9/urllib/request.py", line 494, in _call_chain
    result = func(*args)
  File "/usr/lib/python3.9/urllib/request.py", line 1375, in http_open
    return self.do_open(http.client.HTTPConnection, req)
  File "/usr/lib/python3.9/urllib/request.py", line 1349, in do_open
    raise URLError(err)
urllib.error.URLError: <urlopen error [Errno 111] Connection refused>
2024-11-21 14:18:52,466 [INFO] Freezing in a spot
2024-11-21 14:18:52,467 [INFO] Connection attempt 34, max_reconnection_attempts 180
2024-11-21 14:18:53,522 [ERROR] ConnectionWatchdog - Network is unreachable: 
Traceback (most recent call last):
  File "/usr/lib/python3.9/urllib/request.py", line 1346, in do_open
    h.request(req.get_method(), req.selector, req.data, headers,
  File "/usr/lib/python3.9/http/client.py", line 1255, in request
    self._send_request(method, url, body, headers, encode_chunked)
  File "/usr/lib/python3.9/http/client.py", line 1301, in _send_request
    self.endheaders(body, encode_chunked=encode_chunked)
  File "/usr/lib/python3.9/http/client.py", line 1250, in endheaders
    self._send_output(message_body, encode_chunked=encode_chunked)
  File "/usr/lib/python3.9/http/client.py", line 1010, in _send_output
    self.send(msg)
  File "/usr/lib/python3.9/http/client.py", line 950, in send
    self.connect()
  File "/usr/lib/python3.9/http/client.py", line 921, in connect
    self.sock = self._create_connection(
  File "/usr/lib/python3.9/socket.py", line 843, in create_connection
    raise err
  File "/usr/lib/python3.9/socket.py", line 831, in create_connection
    sock.connect(sa)
ConnectionRefusedError: [Errno 111] Connection refused

During handling of the above exception, another exception occurred:

Traceback (most recent call last):
  File "/home/gourav/raspi-app/connection_watchdog.py", line 40, in is_internet_on
    urlopen(str('http://' + self.host_ip), timeout=5)
  File "/usr/lib/python3.9/urllib/request.py", line 214, in urlopen
    return opener.open(url, data, timeout)
  File "/usr/lib/python3.9/urllib/request.py", line 517, in open
    response = self._open(req, data)
  File "/usr/lib/python3.9/urllib/request.py", line 534, in _open
    result = self._call_chain(self.handle_open, protocol, protocol +
  File "/usr/lib/python3.9/urllib/request.py", line 494, in _call_chain
    result = func(*args)
  File "/usr/lib/python3.9/urllib/request.py", line 1375, in http_open
    return self.do_open(http.client.HTTPConnection, req)
  File "/usr/lib/python3.9/urllib/request.py", line 1349, in do_open
    raise URLError(err)
urllib.error.URLError: <urlopen error [Errno 111] Connection refused>
2024-11-21 14:18:53,526 [INFO] Freezing in a spot
2024-11-21 14:18:53,528 [INFO] Connection attempt 35, max_reconnection_attempts 180
2024-11-21 14:18:54,636 [ERROR] ConnectionWatchdog - Network is unreachable: 
Traceback (most recent call last):
  File "/usr/lib/python3.9/urllib/request.py", line 1346, in do_open
    h.request(req.get_method(), req.selector, req.data, headers,
  File "/usr/lib/python3.9/http/client.py", line 1255, in request
    self._send_request(method, url, body, headers, encode_chunked)
  File "/usr/lib/python3.9/http/client.py", line 1301, in _send_request
    self.endheaders(body, encode_chunked=encode_chunked)
  File "/usr/lib/python3.9/http/client.py", line 1250, in endheaders
    self._send_output(message_body, encode_chunked=encode_chunked)
  File "/usr/lib/python3.9/http/client.py", line 1010, in _send_output
    self.send(msg)
  File "/usr/lib/python3.9/http/client.py", line 950, in send
    self.connect()
  File "/usr/lib/python3.9/http/client.py", line 921, in connect
    self.sock = self._create_connection(
  File "/usr/lib/python3.9/socket.py", line 843, in create_connection
    raise err
  File "/usr/lib/python3.9/socket.py", line 831, in create_connection
    sock.connect(sa)
ConnectionRefusedError: [Errno 111] Connection refused

During handling of the above exception, another exception occurred:

Traceback (most recent call last):
  File "/home/gourav/raspi-app/connection_watchdog.py", line 40, in is_internet_on
    urlopen(str('http://' + self.host_ip), timeout=5)
  File "/usr/lib/python3.9/urllib/request.py", line 214, in urlopen
    return opener.open(url, data, timeout)
  File "/usr/lib/python3.9/urllib/request.py", line 517, in open
    response = self._open(req, data)
  File "/usr/lib/python3.9/urllib/request.py", line 534, in _open
    result = self._call_chain(self.handle_open, protocol, protocol +
  File "/usr/lib/python3.9/urllib/request.py", line 494, in _call_chain
    result = func(*args)
  File "/usr/lib/python3.9/urllib/request.py", line 1375, in http_open
    return self.do_open(http.client.HTTPConnection, req)
  File "/usr/lib/python3.9/urllib/request.py", line 1349, in do_open
    raise URLError(err)
urllib.error.URLError: <urlopen error [Errno 111] Connection refused>
2024-11-21 14:18:54,639 [INFO] Freezing in a spot
2024-11-21 14:18:54,641 [INFO] Connection attempt 36, max_reconnection_attempts 180
2024-11-21 14:18:55,702 [ERROR] ConnectionWatchdog - Network is unreachable: 
Traceback (most recent call last):
  File "/usr/lib/python3.9/urllib/request.py", line 1346, in do_open
    h.request(req.get_method(), req.selector, req.data, headers,
  File "/usr/lib/python3.9/http/client.py", line 1255, in request
    self._send_request(method, url, body, headers, encode_chunked)
  File "/usr/lib/python3.9/http/client.py", line 1301, in _send_request
    self.endheaders(body, encode_chunked=encode_chunked)
  File "/usr/lib/python3.9/http/client.py", line 1250, in endheaders
    self._send_output(message_body, encode_chunked=encode_chunked)
  File "/usr/lib/python3.9/http/client.py", line 1010, in _send_output
    self.send(msg)
  File "/usr/lib/python3.9/http/client.py", line 950, in send
    self.connect()
  File "/usr/lib/python3.9/http/client.py", line 921, in connect
    self.sock = self._create_connection(
  File "/usr/lib/python3.9/socket.py", line 843, in create_connection
    raise err
  File "/usr/lib/python3.9/socket.py", line 831, in create_connection
    sock.connect(sa)
ConnectionRefusedError: [Errno 111] Connection refused

During handling of the above exception, another exception occurred:

Traceback (most recent call last):
  File "/home/gourav/raspi-app/connection_watchdog.py", line 40, in is_internet_on
    urlopen(str('http://' + self.host_ip), timeout=5)
  File "/usr/lib/python3.9/urllib/request.py", line 214, in urlopen
    return opener.open(url, data, timeout)
  File "/usr/lib/python3.9/urllib/request.py", line 517, in open
    response = self._open(req, data)
  File "/usr/lib/python3.9/urllib/request.py", line 534, in _open
    result = self._call_chain(self.handle_open, protocol, protocol +
  File "/usr/lib/python3.9/urllib/request.py", line 494, in _call_chain
    result = func(*args)
  File "/usr/lib/python3.9/urllib/request.py", line 1375, in http_open
    return self.do_open(http.client.HTTPConnection, req)
  File "/usr/lib/python3.9/urllib/request.py", line 1349, in do_open
    raise URLError(err)
urllib.error.URLError: <urlopen error [Errno 111] Connection refused>
2024-11-21 14:18:55,704 [INFO] Freezing in a spot
2024-11-21 14:18:55,706 [INFO] Connection attempt 37, max_reconnection_attempts 180
2024-11-21 14:18:56,767 [ERROR] ConnectionWatchdog - Network is unreachable: 
Traceback (most recent call last):
  File "/usr/lib/python3.9/urllib/request.py", line 1346, in do_open
    h.request(req.get_method(), req.selector, req.data, headers,
  File "/usr/lib/python3.9/http/client.py", line 1255, in request
    self._send_request(method, url, body, headers, encode_chunked)
  File "/usr/lib/python3.9/http/client.py", line 1301, in _send_request
    self.endheaders(body, encode_chunked=encode_chunked)
  File "/usr/lib/python3.9/http/client.py", line 1250, in endheaders
    self._send_output(message_body, encode_chunked=encode_chunked)
  File "/usr/lib/python3.9/http/client.py", line 1010, in _send_output
    self.send(msg)
  File "/usr/lib/python3.9/http/client.py", line 950, in send
    self.connect()
  File "/usr/lib/python3.9/http/client.py", line 921, in connect
    self.sock = self._create_connection(
  File "/usr/lib/python3.9/socket.py", line 843, in create_connection
    raise err
  File "/usr/lib/python3.9/socket.py", line 831, in create_connection
    sock.connect(sa)
ConnectionRefusedError: [Errno 111] Connection refused

During handling of the above exception, another exception occurred:

Traceback (most recent call last):
  File "/home/gourav/raspi-app/connection_watchdog.py", line 40, in is_internet_on
    urlopen(str('http://' + self.host_ip), timeout=5)
  File "/usr/lib/python3.9/urllib/request.py", line 214, in urlopen
    return opener.open(url, data, timeout)
  File "/usr/lib/python3.9/urllib/request.py", line 517, in open
    response = self._open(req, data)
  File "/usr/lib/python3.9/urllib/request.py", line 534, in _open
    result = self._call_chain(self.handle_open, protocol, protocol +
  File "/usr/lib/python3.9/urllib/request.py", line 494, in _call_chain
    result = func(*args)
  File "/usr/lib/python3.9/urllib/request.py", line 1375, in http_open
    return self.do_open(http.client.HTTPConnection, req)
  File "/usr/lib/python3.9/urllib/request.py", line 1349, in do_open
    raise URLError(err)
urllib.error.URLError: <urlopen error [Errno 111] Connection refused>
2024-11-21 14:18:56,770 [INFO] Freezing in a spot
2024-11-21 14:18:56,772 [INFO] Connection attempt 38, max_reconnection_attempts 180
2024-11-21 14:18:57,873 [ERROR] ConnectionWatchdog - Network is unreachable: 
Traceback (most recent call last):
  File "/usr/lib/python3.9/urllib/request.py", line 1346, in do_open
    h.request(req.get_method(), req.selector, req.data, headers,
  File "/usr/lib/python3.9/http/client.py", line 1255, in request
    self._send_request(method, url, body, headers, encode_chunked)
  File "/usr/lib/python3.9/http/client.py", line 1301, in _send_request
    self.endheaders(body, encode_chunked=encode_chunked)
  File "/usr/lib/python3.9/http/client.py", line 1250, in endheaders
    self._send_output(message_body, encode_chunked=encode_chunked)
  File "/usr/lib/python3.9/http/client.py", line 1010, in _send_output
    self.send(msg)
  File "/usr/lib/python3.9/http/client.py", line 950, in send
    self.connect()
  File "/usr/lib/python3.9/http/client.py", line 921, in connect
    self.sock = self._create_connection(
  File "/usr/lib/python3.9/socket.py", line 843, in create_connection
    raise err
  File "/usr/lib/python3.9/socket.py", line 831, in create_connection
    sock.connect(sa)
ConnectionRefusedError: [Errno 111] Connection refused

During handling of the above exception, another exception occurred:

Traceback (most recent call last):
  File "/home/gourav/raspi-app/connection_watchdog.py", line 40, in is_internet_on
    urlopen(str('http://' + self.host_ip), timeout=5)
  File "/usr/lib/python3.9/urllib/request.py", line 214, in urlopen
    return opener.open(url, data, timeout)
  File "/usr/lib/python3.9/urllib/request.py", line 517, in open
    response = self._open(req, data)
  File "/usr/lib/python3.9/urllib/request.py", line 534, in _open
    result = self._call_chain(self.handle_open, protocol, protocol +
  File "/usr/lib/python3.9/urllib/request.py", line 494, in _call_chain
    result = func(*args)
  File "/usr/lib/python3.9/urllib/request.py", line 1375, in http_open
    return self.do_open(http.client.HTTPConnection, req)
  File "/usr/lib/python3.9/urllib/request.py", line 1349, in do_open
    raise URLError(err)
urllib.error.URLError: <urlopen error [Errno 111] Connection refused>
2024-11-21 14:18:57,876 [INFO] Freezing in a spot
2024-11-21 14:18:57,878 [INFO] Connection attempt 39, max_reconnection_attempts 180
2024-11-21 14:18:58,932 [ERROR] ConnectionWatchdog - Network is unreachable: 
Traceback (most recent call last):
  File "/usr/lib/python3.9/urllib/request.py", line 1346, in do_open
    h.request(req.get_method(), req.selector, req.data, headers,
  File "/usr/lib/python3.9/http/client.py", line 1255, in request
    self._send_request(method, url, body, headers, encode_chunked)
  File "/usr/lib/python3.9/http/client.py", line 1301, in _send_request
    self.endheaders(body, encode_chunked=encode_chunked)
  File "/usr/lib/python3.9/http/client.py", line 1250, in endheaders
    self._send_output(message_body, encode_chunked=encode_chunked)
  File "/usr/lib/python3.9/http/client.py", line 1010, in _send_output
    self.send(msg)
  File "/usr/lib/python3.9/http/client.py", line 950, in send
    self.connect()
  File "/usr/lib/python3.9/http/client.py", line 921, in connect
    self.sock = self._create_connection(
  File "/usr/lib/python3.9/socket.py", line 843, in create_connection
    raise err
  File "/usr/lib/python3.9/socket.py", line 831, in create_connection
    sock.connect(sa)
ConnectionRefusedError: [Errno 111] Connection refused

During handling of the above exception, another exception occurred:

Traceback (most recent call last):
  File "/home/gourav/raspi-app/connection_watchdog.py", line 40, in is_internet_on
    urlopen(str('http://' + self.host_ip), timeout=5)
  File "/usr/lib/python3.9/urllib/request.py", line 214, in urlopen
    return opener.open(url, data, timeout)
  File "/usr/lib/python3.9/urllib/request.py", line 517, in open
    response = self._open(req, data)
  File "/usr/lib/python3.9/urllib/request.py", line 534, in _open
    result = self._call_chain(self.handle_open, protocol, protocol +
  File "/usr/lib/python3.9/urllib/request.py", line 494, in _call_chain
    result = func(*args)
  File "/usr/lib/python3.9/urllib/request.py", line 1375, in http_open
    return self.do_open(http.client.HTTPConnection, req)
  File "/usr/lib/python3.9/urllib/request.py", line 1349, in do_open
    raise URLError(err)
urllib.error.URLError: <urlopen error [Errno 111] Connection refused>
2024-11-21 14:18:58,935 [INFO] Freezing in a spot
2024-11-21 14:18:58,936 [INFO] Connection attempt 40, max_reconnection_attempts 180
2024-11-21 14:19:00,002 [ERROR] ConnectionWatchdog - Network is unreachable: 
Traceback (most recent call last):
  File "/usr/lib/python3.9/urllib/request.py", line 1346, in do_open
    h.request(req.get_method(), req.selector, req.data, headers,
  File "/usr/lib/python3.9/http/client.py", line 1255, in request
    self._send_request(method, url, body, headers, encode_chunked)
  File "/usr/lib/python3.9/http/client.py", line 1301, in _send_request
    self.endheaders(body, encode_chunked=encode_chunked)
  File "/usr/lib/python3.9/http/client.py", line 1250, in endheaders
    self._send_output(message_body, encode_chunked=encode_chunked)
  File "/usr/lib/python3.9/http/client.py", line 1010, in _send_output
    self.send(msg)
  File "/usr/lib/python3.9/http/client.py", line 950, in send
    self.connect()
  File "/usr/lib/python3.9/http/client.py", line 921, in connect
    self.sock = self._create_connection(
  File "/usr/lib/python3.9/socket.py", line 843, in create_connection
    raise err
  File "/usr/lib/python3.9/socket.py", line 831, in create_connection
    sock.connect(sa)
ConnectionRefusedError: [Errno 111] Connection refused

During handling of the above exception, another exception occurred:

Traceback (most recent call last):
  File "/home/gourav/raspi-app/connection_watchdog.py", line 40, in is_internet_on
    urlopen(str('http://' + self.host_ip), timeout=5)
  File "/usr/lib/python3.9/urllib/request.py", line 214, in urlopen
    return opener.open(url, data, timeout)
  File "/usr/lib/python3.9/urllib/request.py", line 517, in open
    response = self._open(req, data)
  File "/usr/lib/python3.9/urllib/request.py", line 534, in _open
    result = self._call_chain(self.handle_open, protocol, protocol +
  File "/usr/lib/python3.9/urllib/request.py", line 494, in _call_chain
    result = func(*args)
  File "/usr/lib/python3.9/urllib/request.py", line 1375, in http_open
    return self.do_open(http.client.HTTPConnection, req)
  File "/usr/lib/python3.9/urllib/request.py", line 1349, in do_open
    raise URLError(err)
urllib.error.URLError: <urlopen error [Errno 111] Connection refused>
2024-11-21 14:19:00,004 [INFO] Freezing in a spot
2024-11-21 14:19:00,005 [INFO] Connection attempt 41, max_reconnection_attempts 180
2024-11-21 14:19:01,102 [ERROR] ConnectionWatchdog - Network is unreachable: 
Traceback (most recent call last):
  File "/usr/lib/python3.9/urllib/request.py", line 1346, in do_open
    h.request(req.get_method(), req.selector, req.data, headers,
  File "/usr/lib/python3.9/http/client.py", line 1255, in request
    self._send_request(method, url, body, headers, encode_chunked)
  File "/usr/lib/python3.9/http/client.py", line 1301, in _send_request
    self.endheaders(body, encode_chunked=encode_chunked)
  File "/usr/lib/python3.9/http/client.py", line 1250, in endheaders
    self._send_output(message_body, encode_chunked=encode_chunked)
  File "/usr/lib/python3.9/http/client.py", line 1010, in _send_output
    self.send(msg)
  File "/usr/lib/python3.9/http/client.py", line 950, in send
    self.connect()
  File "/usr/lib/python3.9/http/client.py", line 921, in connect
    self.sock = self._create_connection(
  File "/usr/lib/python3.9/socket.py", line 843, in create_connection
    raise err
  File "/usr/lib/python3.9/socket.py", line 831, in create_connection
    sock.connect(sa)
ConnectionRefusedError: [Errno 111] Connection refused

During handling of the above exception, another exception occurred:

Traceback (most recent call last):
  File "/home/gourav/raspi-app/connection_watchdog.py", line 40, in is_internet_on
    urlopen(str('http://' + self.host_ip), timeout=5)
  File "/usr/lib/python3.9/urllib/request.py", line 214, in urlopen
    return opener.open(url, data, timeout)
  File "/usr/lib/python3.9/urllib/request.py", line 517, in open
    response = self._open(req, data)
  File "/usr/lib/python3.9/urllib/request.py", line 534, in _open
    result = self._call_chain(self.handle_open, protocol, protocol +
  File "/usr/lib/python3.9/urllib/request.py", line 494, in _call_chain
    result = func(*args)
  File "/usr/lib/python3.9/urllib/request.py", line 1375, in http_open
    return self.do_open(http.client.HTTPConnection, req)
  File "/usr/lib/python3.9/urllib/request.py", line 1349, in do_open
    raise URLError(err)
urllib.error.URLError: <urlopen error [Errno 111] Connection refused>
2024-11-21 14:19:01,108 [INFO] Freezing in a spot
2024-11-21 14:19:01,116 [INFO] Connection attempt 42, max_reconnection_attempts 180
2024-11-21 14:19:02,211 [ERROR] ConnectionWatchdog - Network is unreachable: 
Traceback (most recent call last):
  File "/usr/lib/python3.9/urllib/request.py", line 1346, in do_open
    h.request(req.get_method(), req.selector, req.data, headers,
  File "/usr/lib/python3.9/http/client.py", line 1255, in request
    self._send_request(method, url, body, headers, encode_chunked)
  File "/usr/lib/python3.9/http/client.py", line 1301, in _send_request
    self.endheaders(body, encode_chunked=encode_chunked)
  File "/usr/lib/python3.9/http/client.py", line 1250, in endheaders
    self._send_output(message_body, encode_chunked=encode_chunked)
  File "/usr/lib/python3.9/http/client.py", line 1010, in _send_output
    self.send(msg)
  File "/usr/lib/python3.9/http/client.py", line 950, in send
    self.connect()
  File "/usr/lib/python3.9/http/client.py", line 921, in connect
    self.sock = self._create_connection(
  File "/usr/lib/python3.9/socket.py", line 843, in create_connection
    raise err
  File "/usr/lib/python3.9/socket.py", line 831, in create_connection
    sock.connect(sa)
ConnectionRefusedError: [Errno 111] Connection refused

During handling of the above exception, another exception occurred:

Traceback (most recent call last):
  File "/home/gourav/raspi-app/connection_watchdog.py", line 40, in is_internet_on
    urlopen(str('http://' + self.host_ip), timeout=5)
  File "/usr/lib/python3.9/urllib/request.py", line 214, in urlopen
    return opener.open(url, data, timeout)
  File "/usr/lib/python3.9/urllib/request.py", line 517, in open
    response = self._open(req, data)
  File "/usr/lib/python3.9/urllib/request.py", line 534, in _open
    result = self._call_chain(self.handle_open, protocol, protocol +
  File "/usr/lib/python3.9/urllib/request.py", line 494, in _call_chain
    result = func(*args)
  File "/usr/lib/python3.9/urllib/request.py", line 1375, in http_open
    return self.do_open(http.client.HTTPConnection, req)
  File "/usr/lib/python3.9/urllib/request.py", line 1349, in do_open
    raise URLError(err)
urllib.error.URLError: <urlopen error [Errno 111] Connection refused>
2024-11-21 14:19:02,215 [INFO] Freezing in a spot
2024-11-21 14:19:02,217 [INFO] Connection attempt 43, max_reconnection_attempts 180
2024-11-21 14:19:03,273 [ERROR] ConnectionWatchdog - Network is unreachable: 
Traceback (most recent call last):
  File "/usr/lib/python3.9/urllib/request.py", line 1346, in do_open
    h.request(req.get_method(), req.selector, req.data, headers,
  File "/usr/lib/python3.9/http/client.py", line 1255, in request
    self._send_request(method, url, body, headers, encode_chunked)
  File "/usr/lib/python3.9/http/client.py", line 1301, in _send_request
    self.endheaders(body, encode_chunked=encode_chunked)
  File "/usr/lib/python3.9/http/client.py", line 1250, in endheaders
    self._send_output(message_body, encode_chunked=encode_chunked)
  File "/usr/lib/python3.9/http/client.py", line 1010, in _send_output
    self.send(msg)
  File "/usr/lib/python3.9/http/client.py", line 950, in send
    self.connect()
  File "/usr/lib/python3.9/http/client.py", line 921, in connect
    self.sock = self._create_connection(
  File "/usr/lib/python3.9/socket.py", line 843, in create_connection
    raise err
  File "/usr/lib/python3.9/socket.py", line 831, in create_connection
    sock.connect(sa)
ConnectionRefusedError: [Errno 111] Connection refused

During handling of the above exception, another exception occurred:

Traceback (most recent call last):
  File "/home/gourav/raspi-app/connection_watchdog.py", line 40, in is_internet_on
    urlopen(str('http://' + self.host_ip), timeout=5)
  File "/usr/lib/python3.9/urllib/request.py", line 214, in urlopen
    return opener.open(url, data, timeout)
  File "/usr/lib/python3.9/urllib/request.py", line 517, in open
    response = self._open(req, data)
  File "/usr/lib/python3.9/urllib/request.py", line 534, in _open
    result = self._call_chain(self.handle_open, protocol, protocol +
  File "/usr/lib/python3.9/urllib/request.py", line 494, in _call_chain
    result = func(*args)
  File "/usr/lib/python3.9/urllib/request.py", line 1375, in http_open
    return self.do_open(http.client.HTTPConnection, req)
  File "/usr/lib/python3.9/urllib/request.py", line 1349, in do_open
    raise URLError(err)
urllib.error.URLError: <urlopen error [Errno 111] Connection refused>
2024-11-21 14:19:03,277 [INFO] Freezing in a spot
2024-11-21 14:19:03,278 [INFO] Connection attempt 44, max_reconnection_attempts 180
2024-11-21 14:19:04,392 [ERROR] ConnectionWatchdog - Network is unreachable: 
Traceback (most recent call last):
  File "/usr/lib/python3.9/urllib/request.py", line 1346, in do_open
    h.request(req.get_method(), req.selector, req.data, headers,
  File "/usr/lib/python3.9/http/client.py", line 1255, in request
    self._send_request(method, url, body, headers, encode_chunked)
  File "/usr/lib/python3.9/http/client.py", line 1301, in _send_request
    self.endheaders(body, encode_chunked=encode_chunked)
  File "/usr/lib/python3.9/http/client.py", line 1250, in endheaders
    self._send_output(message_body, encode_chunked=encode_chunked)
  File "/usr/lib/python3.9/http/client.py", line 1010, in _send_output
    self.send(msg)
  File "/usr/lib/python3.9/http/client.py", line 950, in send
    self.connect()
  File "/usr/lib/python3.9/http/client.py", line 921, in connect
    self.sock = self._create_connection(
  File "/usr/lib/python3.9/socket.py", line 843, in create_connection
    raise err
  File "/usr/lib/python3.9/socket.py", line 831, in create_connection
    sock.connect(sa)
ConnectionRefusedError: [Errno 111] Connection refused

During handling of the above exception, another exception occurred:

Traceback (most recent call last):
  File "/home/gourav/raspi-app/connection_watchdog.py", line 40, in is_internet_on
    urlopen(str('http://' + self.host_ip), timeout=5)
  File "/usr/lib/python3.9/urllib/request.py", line 214, in urlopen
    return opener.open(url, data, timeout)
  File "/usr/lib/python3.9/urllib/request.py", line 517, in open
    response = self._open(req, data)
  File "/usr/lib/python3.9/urllib/request.py", line 534, in _open
    result = self._call_chain(self.handle_open, protocol, protocol +
  File "/usr/lib/python3.9/urllib/request.py", line 494, in _call_chain
    result = func(*args)
  File "/usr/lib/python3.9/urllib/request.py", line 1375, in http_open
    return self.do_open(http.client.HTTPConnection, req)
  File "/usr/lib/python3.9/urllib/request.py", line 1349, in do_open
    raise URLError(err)
urllib.error.URLError: <urlopen error [Errno 111] Connection refused>
2024-11-21 14:19:04,395 [INFO] Freezing in a spot
2024-11-21 14:19:04,396 [INFO] Connection attempt 45, max_reconnection_attempts 180
2024-11-21 14:19:05,494 [ERROR] ConnectionWatchdog - Network is unreachable: 
Traceback (most recent call last):
  File "/usr/lib/python3.9/urllib/request.py", line 1346, in do_open
    h.request(req.get_method(), req.selector, req.data, headers,
  File "/usr/lib/python3.9/http/client.py", line 1255, in request
    self._send_request(method, url, body, headers, encode_chunked)
  File "/usr/lib/python3.9/http/client.py", line 1301, in _send_request
    self.endheaders(body, encode_chunked=encode_chunked)
  File "/usr/lib/python3.9/http/client.py", line 1250, in endheaders
    self._send_output(message_body, encode_chunked=encode_chunked)
  File "/usr/lib/python3.9/http/client.py", line 1010, in _send_output
    self.send(msg)
  File "/usr/lib/python3.9/http/client.py", line 950, in send
    self.connect()
  File "/usr/lib/python3.9/http/client.py", line 921, in connect
    self.sock = self._create_connection(
  File "/usr/lib/python3.9/socket.py", line 843, in create_connection
    raise err
  File "/usr/lib/python3.9/socket.py", line 831, in create_connection
    sock.connect(sa)
ConnectionRefusedError: [Errno 111] Connection refused

During handling of the above exception, another exception occurred:

Traceback (most recent call last):
  File "/home/gourav/raspi-app/connection_watchdog.py", line 40, in is_internet_on
    urlopen(str('http://' + self.host_ip), timeout=5)
  File "/usr/lib/python3.9/urllib/request.py", line 214, in urlopen
    return opener.open(url, data, timeout)
  File "/usr/lib/python3.9/urllib/request.py", line 517, in open
    response = self._open(req, data)
  File "/usr/lib/python3.9/urllib/request.py", line 534, in _open
    result = self._call_chain(self.handle_open, protocol, protocol +
  File "/usr/lib/python3.9/urllib/request.py", line 494, in _call_chain
    result = func(*args)
  File "/usr/lib/python3.9/urllib/request.py", line 1375, in http_open
    return self.do_open(http.client.HTTPConnection, req)
  File "/usr/lib/python3.9/urllib/request.py", line 1349, in do_open
    raise URLError(err)
urllib.error.URLError: <urlopen error [Errno 111] Connection refused>
2024-11-21 14:19:05,496 [INFO] Freezing in a spot
2024-11-21 14:19:05,498 [INFO] Connection attempt 46, max_reconnection_attempts 180
2024-11-21 14:19:06,552 [ERROR] ConnectionWatchdog - Network is unreachable: 
Traceback (most recent call last):
  File "/usr/lib/python3.9/urllib/request.py", line 1346, in do_open
    h.request(req.get_method(), req.selector, req.data, headers,
  File "/usr/lib/python3.9/http/client.py", line 1255, in request
    self._send_request(method, url, body, headers, encode_chunked)
  File "/usr/lib/python3.9/http/client.py", line 1301, in _send_request
    self.endheaders(body, encode_chunked=encode_chunked)
  File "/usr/lib/python3.9/http/client.py", line 1250, in endheaders
    self._send_output(message_body, encode_chunked=encode_chunked)
  File "/usr/lib/python3.9/http/client.py", line 1010, in _send_output
    self.send(msg)
  File "/usr/lib/python3.9/http/client.py", line 950, in send
    self.connect()
  File "/usr/lib/python3.9/http/client.py", line 921, in connect
    self.sock = self._create_connection(
  File "/usr/lib/python3.9/socket.py", line 843, in create_connection
    raise err
  File "/usr/lib/python3.9/socket.py", line 831, in create_connection
    sock.connect(sa)
ConnectionRefusedError: [Errno 111] Connection refused

During handling of the above exception, another exception occurred:

Traceback (most recent call last):
  File "/home/gourav/raspi-app/connection_watchdog.py", line 40, in is_internet_on
    urlopen(str('http://' + self.host_ip), timeout=5)
  File "/usr/lib/python3.9/urllib/request.py", line 214, in urlopen
    return opener.open(url, data, timeout)
  File "/usr/lib/python3.9/urllib/request.py", line 517, in open
    response = self._open(req, data)
  File "/usr/lib/python3.9/urllib/request.py", line 534, in _open
    result = self._call_chain(self.handle_open, protocol, protocol +
  File "/usr/lib/python3.9/urllib/request.py", line 494, in _call_chain
    result = func(*args)
  File "/usr/lib/python3.9/urllib/request.py", line 1375, in http_open
    return self.do_open(http.client.HTTPConnection, req)
  File "/usr/lib/python3.9/urllib/request.py", line 1349, in do_open
    raise URLError(err)
urllib.error.URLError: <urlopen error [Errno 111] Connection refused>
2024-11-21 14:19:06,557 [INFO] Freezing in a spot
2024-11-21 14:19:06,559 [INFO] Connection attempt 47, max_reconnection_attempts 180
2024-11-21 14:19:07,632 [ERROR] ConnectionWatchdog - Network is unreachable: 
Traceback (most recent call last):
  File "/usr/lib/python3.9/urllib/request.py", line 1346, in do_open
    h.request(req.get_method(), req.selector, req.data, headers,
  File "/usr/lib/python3.9/http/client.py", line 1255, in request
    self._send_request(method, url, body, headers, encode_chunked)
  File "/usr/lib/python3.9/http/client.py", line 1301, in _send_request
    self.endheaders(body, encode_chunked=encode_chunked)
  File "/usr/lib/python3.9/http/client.py", line 1250, in endheaders
    self._send_output(message_body, encode_chunked=encode_chunked)
  File "/usr/lib/python3.9/http/client.py", line 1010, in _send_output
    self.send(msg)
  File "/usr/lib/python3.9/http/client.py", line 950, in send
    self.connect()
  File "/usr/lib/python3.9/http/client.py", line 921, in connect
    self.sock = self._create_connection(
  File "/usr/lib/python3.9/socket.py", line 843, in create_connection
    raise err
  File "/usr/lib/python3.9/socket.py", line 831, in create_connection
    sock.connect(sa)
ConnectionRefusedError: [Errno 111] Connection refused

During handling of the above exception, another exception occurred:

Traceback (most recent call last):
  File "/home/gourav/raspi-app/connection_watchdog.py", line 40, in is_internet_on
    urlopen(str('http://' + self.host_ip), timeout=5)
  File "/usr/lib/python3.9/urllib/request.py", line 214, in urlopen
    return opener.open(url, data, timeout)
  File "/usr/lib/python3.9/urllib/request.py", line 517, in open
    response = self._open(req, data)
  File "/usr/lib/python3.9/urllib/request.py", line 534, in _open
    result = self._call_chain(self.handle_open, protocol, protocol +
  File "/usr/lib/python3.9/urllib/request.py", line 494, in _call_chain
    result = func(*args)
  File "/usr/lib/python3.9/urllib/request.py", line 1375, in http_open
    return self.do_open(http.client.HTTPConnection, req)
  File "/usr/lib/python3.9/urllib/request.py", line 1349, in do_open
    raise URLError(err)
urllib.error.URLError: <urlopen error [Errno 111] Connection refused>
2024-11-21 14:19:07,636 [INFO] Freezing in a spot
2024-11-21 14:19:07,637 [INFO] Connection attempt 48, max_reconnection_attempts 180
2024-11-21 14:19:08,722 [ERROR] ConnectionWatchdog - Network is unreachable: 
Traceback (most recent call last):
  File "/usr/lib/python3.9/urllib/request.py", line 1346, in do_open
    h.request(req.get_method(), req.selector, req.data, headers,
  File "/usr/lib/python3.9/http/client.py", line 1255, in request
    self._send_request(method, url, body, headers, encode_chunked)
  File "/usr/lib/python3.9/http/client.py", line 1301, in _send_request
    self.endheaders(body, encode_chunked=encode_chunked)
  File "/usr/lib/python3.9/http/client.py", line 1250, in endheaders
    self._send_output(message_body, encode_chunked=encode_chunked)
  File "/usr/lib/python3.9/http/client.py", line 1010, in _send_output
    self.send(msg)
  File "/usr/lib/python3.9/http/client.py", line 950, in send
    self.connect()
  File "/usr/lib/python3.9/http/client.py", line 921, in connect
    self.sock = self._create_connection(
  File "/usr/lib/python3.9/socket.py", line 843, in create_connection
    raise err
  File "/usr/lib/python3.9/socket.py", line 831, in create_connection
    sock.connect(sa)
ConnectionRefusedError: [Errno 111] Connection refused

During handling of the above exception, another exception occurred:

Traceback (most recent call last):
  File "/home/gourav/raspi-app/connection_watchdog.py", line 40, in is_internet_on
    urlopen(str('http://' + self.host_ip), timeout=5)
  File "/usr/lib/python3.9/urllib/request.py", line 214, in urlopen
    return opener.open(url, data, timeout)
  File "/usr/lib/python3.9/urllib/request.py", line 517, in open
    response = self._open(req, data)
  File "/usr/lib/python3.9/urllib/request.py", line 534, in _open
    result = self._call_chain(self.handle_open, protocol, protocol +
  File "/usr/lib/python3.9/urllib/request.py", line 494, in _call_chain
    result = func(*args)
  File "/usr/lib/python3.9/urllib/request.py", line 1375, in http_open
    return self.do_open(http.client.HTTPConnection, req)
  File "/usr/lib/python3.9/urllib/request.py", line 1349, in do_open
    raise URLError(err)
urllib.error.URLError: <urlopen error [Errno 111] Connection refused>
2024-11-21 14:19:08,726 [INFO] Freezing in a spot
2024-11-21 14:19:08,727 [INFO] Connection attempt 49, max_reconnection_attempts 180
2024-11-21 14:19:09,843 [ERROR] ConnectionWatchdog - Network is unreachable: 
Traceback (most recent call last):
  File "/usr/lib/python3.9/urllib/request.py", line 1346, in do_open
    h.request(req.get_method(), req.selector, req.data, headers,
  File "/usr/lib/python3.9/http/client.py", line 1255, in request
    self._send_request(method, url, body, headers, encode_chunked)
  File "/usr/lib/python3.9/http/client.py", line 1301, in _send_request
    self.endheaders(body, encode_chunked=encode_chunked)
  File "/usr/lib/python3.9/http/client.py", line 1250, in endheaders
    self._send_output(message_body, encode_chunked=encode_chunked)
  File "/usr/lib/python3.9/http/client.py", line 1010, in _send_output
    self.send(msg)
  File "/usr/lib/python3.9/http/client.py", line 950, in send
    self.connect()
  File "/usr/lib/python3.9/http/client.py", line 921, in connect
    self.sock = self._create_connection(
  File "/usr/lib/python3.9/socket.py", line 843, in create_connection
    raise err
  File "/usr/lib/python3.9/socket.py", line 831, in create_connection
    sock.connect(sa)
ConnectionRefusedError: [Errno 111] Connection refused

During handling of the above exception, another exception occurred:

Traceback (most recent call last):
  File "/home/gourav/raspi-app/connection_watchdog.py", line 40, in is_internet_on
    urlopen(str('http://' + self.host_ip), timeout=5)
  File "/usr/lib/python3.9/urllib/request.py", line 214, in urlopen
    return opener.open(url, data, timeout)
  File "/usr/lib/python3.9/urllib/request.py", line 517, in open
    response = self._open(req, data)
  File "/usr/lib/python3.9/urllib/request.py", line 534, in _open
    result = self._call_chain(self.handle_open, protocol, protocol +
  File "/usr/lib/python3.9/urllib/request.py", line 494, in _call_chain
    result = func(*args)
  File "/usr/lib/python3.9/urllib/request.py", line 1375, in http_open
    return self.do_open(http.client.HTTPConnection, req)
  File "/usr/lib/python3.9/urllib/request.py", line 1349, in do_open
    raise URLError(err)
urllib.error.URLError: <urlopen error [Errno 111] Connection refused>
2024-11-21 14:19:09,847 [INFO] Freezing in a spot
2024-11-21 14:19:09,848 [INFO] Connection attempt 50, max_reconnection_attempts 180
2024-11-21 14:19:11,011 [ERROR] ConnectionWatchdog - Network is unreachable: 
Traceback (most recent call last):
  File "/usr/lib/python3.9/urllib/request.py", line 1346, in do_open
    h.request(req.get_method(), req.selector, req.data, headers,
  File "/usr/lib/python3.9/http/client.py", line 1255, in request
    self._send_request(method, url, body, headers, encode_chunked)
  File "/usr/lib/python3.9/http/client.py", line 1301, in _send_request
    self.endheaders(body, encode_chunked=encode_chunked)
  File "/usr/lib/python3.9/http/client.py", line 1250, in endheaders
    self._send_output(message_body, encode_chunked=encode_chunked)
  File "/usr/lib/python3.9/http/client.py", line 1010, in _send_output
    self.send(msg)
  File "/usr/lib/python3.9/http/client.py", line 950, in send
    self.connect()
  File "/usr/lib/python3.9/http/client.py", line 921, in connect
    self.sock = self._create_connection(
  File "/usr/lib/python3.9/socket.py", line 843, in create_connection
    raise err
  File "/usr/lib/python3.9/socket.py", line 831, in create_connection
    sock.connect(sa)
ConnectionRefusedError: [Errno 111] Connection refused

During handling of the above exception, another exception occurred:

Traceback (most recent call last):
  File "/home/gourav/raspi-app/connection_watchdog.py", line 40, in is_internet_on
    urlopen(str('http://' + self.host_ip), timeout=5)
  File "/usr/lib/python3.9/urllib/request.py", line 214, in urlopen
    return opener.open(url, data, timeout)
  File "/usr/lib/python3.9/urllib/request.py", line 517, in open
    response = self._open(req, data)
  File "/usr/lib/python3.9/urllib/request.py", line 534, in _open
    result = self._call_chain(self.handle_open, protocol, protocol +
  File "/usr/lib/python3.9/urllib/request.py", line 494, in _call_chain
    result = func(*args)
  File "/usr/lib/python3.9/urllib/request.py", line 1375, in http_open
    return self.do_open(http.client.HTTPConnection, req)
  File "/usr/lib/python3.9/urllib/request.py", line 1349, in do_open
    raise URLError(err)
urllib.error.URLError: <urlopen error [Errno 111] Connection refused>
2024-11-21 14:19:11,029 [INFO] Freezing in a spot
2024-11-21 14:19:11,030 [INFO] Connection attempt 51, max_reconnection_attempts 180
2024-11-21 14:19:12,227 [ERROR] ConnectionWatchdog - Network is unreachable: 
Traceback (most recent call last):
  File "/usr/lib/python3.9/urllib/request.py", line 1346, in do_open
    h.request(req.get_method(), req.selector, req.data, headers,
  File "/usr/lib/python3.9/http/client.py", line 1255, in request
    self._send_request(method, url, body, headers, encode_chunked)
  File "/usr/lib/python3.9/http/client.py", line 1301, in _send_request
    self.endheaders(body, encode_chunked=encode_chunked)
  File "/usr/lib/python3.9/http/client.py", line 1250, in endheaders
    self._send_output(message_body, encode_chunked=encode_chunked)
  File "/usr/lib/python3.9/http/client.py", line 1010, in _send_output
    self.send(msg)
  File "/usr/lib/python3.9/http/client.py", line 950, in send
    self.connect()
  File "/usr/lib/python3.9/http/client.py", line 921, in connect
    self.sock = self._create_connection(
  File "/usr/lib/python3.9/socket.py", line 843, in create_connection
    raise err
  File "/usr/lib/python3.9/socket.py", line 831, in create_connection
    sock.connect(sa)
ConnectionRefusedError: [Errno 111] Connection refused

During handling of the above exception, another exception occurred:

Traceback (most recent call last):
  File "/home/gourav/raspi-app/connection_watchdog.py", line 40, in is_internet_on
    urlopen(str('http://' + self.host_ip), timeout=5)
  File "/usr/lib/python3.9/urllib/request.py", line 214, in urlopen
    return opener.open(url, data, timeout)
  File "/usr/lib/python3.9/urllib/request.py", line 517, in open
    response = self._open(req, data)
  File "/usr/lib/python3.9/urllib/request.py", line 534, in _open
    result = self._call_chain(self.handle_open, protocol, protocol +
  File "/usr/lib/python3.9/urllib/request.py", line 494, in _call_chain
    result = func(*args)
  File "/usr/lib/python3.9/urllib/request.py", line 1375, in http_open
    return self.do_open(http.client.HTTPConnection, req)
  File "/usr/lib/python3.9/urllib/request.py", line 1349, in do_open
    raise URLError(err)
urllib.error.URLError: <urlopen error [Errno 111] Connection refused>
2024-11-21 14:19:12,231 [INFO] Freezing in a spot
2024-11-21 14:19:12,233 [INFO] Connection attempt 52, max_reconnection_attempts 180
2024-11-21 14:19:13,343 [ERROR] ConnectionWatchdog - Network is unreachable: 
Traceback (most recent call last):
  File "/usr/lib/python3.9/urllib/request.py", line 1346, in do_open
    h.request(req.get_method(), req.selector, req.data, headers,
  File "/usr/lib/python3.9/http/client.py", line 1255, in request
    self._send_request(method, url, body, headers, encode_chunked)
  File "/usr/lib/python3.9/http/client.py", line 1301, in _send_request
    self.endheaders(body, encode_chunked=encode_chunked)
  File "/usr/lib/python3.9/http/client.py", line 1250, in endheaders
    self._send_output(message_body, encode_chunked=encode_chunked)
  File "/usr/lib/python3.9/http/client.py", line 1010, in _send_output
    self.send(msg)
  File "/usr/lib/python3.9/http/client.py", line 950, in send
    self.connect()
  File "/usr/lib/python3.9/http/client.py", line 921, in connect
    self.sock = self._create_connection(
  File "/usr/lib/python3.9/socket.py", line 843, in create_connection
    raise err
  File "/usr/lib/python3.9/socket.py", line 831, in create_connection
    sock.connect(sa)
ConnectionRefusedError: [Errno 111] Connection refused

During handling of the above exception, another exception occurred:

Traceback (most recent call last):
  File "/home/gourav/raspi-app/connection_watchdog.py", line 40, in is_internet_on
    urlopen(str('http://' + self.host_ip), timeout=5)
  File "/usr/lib/python3.9/urllib/request.py", line 214, in urlopen
    return opener.open(url, data, timeout)
  File "/usr/lib/python3.9/urllib/request.py", line 517, in open
    response = self._open(req, data)
  File "/usr/lib/python3.9/urllib/request.py", line 534, in _open
    result = self._call_chain(self.handle_open, protocol, protocol +
  File "/usr/lib/python3.9/urllib/request.py", line 494, in _call_chain
    result = func(*args)
  File "/usr/lib/python3.9/urllib/request.py", line 1375, in http_open
    return self.do_open(http.client.HTTPConnection, req)
  File "/usr/lib/python3.9/urllib/request.py", line 1349, in do_open
    raise URLError(err)
urllib.error.URLError: <urlopen error [Errno 111] Connection refused>
2024-11-21 14:19:13,347 [INFO] Freezing in a spot
2024-11-21 14:19:13,348 [INFO] Connection attempt 53, max_reconnection_attempts 180
2024-11-21 14:19:14,427 [ERROR] ConnectionWatchdog - Network is unreachable: 
Traceback (most recent call last):
  File "/usr/lib/python3.9/urllib/request.py", line 1346, in do_open
    h.request(req.get_method(), req.selector, req.data, headers,
  File "/usr/lib/python3.9/http/client.py", line 1255, in request
    self._send_request(method, url, body, headers, encode_chunked)
  File "/usr/lib/python3.9/http/client.py", line 1301, in _send_request
    self.endheaders(body, encode_chunked=encode_chunked)
  File "/usr/lib/python3.9/http/client.py", line 1250, in endheaders
    self._send_output(message_body, encode_chunked=encode_chunked)
  File "/usr/lib/python3.9/http/client.py", line 1010, in _send_output
    self.send(msg)
  File "/usr/lib/python3.9/http/client.py", line 950, in send
    self.connect()
  File "/usr/lib/python3.9/http/client.py", line 921, in connect
    self.sock = self._create_connection(
  File "/usr/lib/python3.9/socket.py", line 843, in create_connection
    raise err
  File "/usr/lib/python3.9/socket.py", line 831, in create_connection
    sock.connect(sa)
ConnectionRefusedError: [Errno 111] Connection refused

During handling of the above exception, another exception occurred:

Traceback (most recent call last):
  File "/home/gourav/raspi-app/connection_watchdog.py", line 40, in is_internet_on
    urlopen(str('http://' + self.host_ip), timeout=5)
  File "/usr/lib/python3.9/urllib/request.py", line 214, in urlopen
    return opener.open(url, data, timeout)
  File "/usr/lib/python3.9/urllib/request.py", line 517, in open
    response = self._open(req, data)
  File "/usr/lib/python3.9/urllib/request.py", line 534, in _open
    result = self._call_chain(self.handle_open, protocol, protocol +
  File "/usr/lib/python3.9/urllib/request.py", line 494, in _call_chain
    result = func(*args)
  File "/usr/lib/python3.9/urllib/request.py", line 1375, in http_open
    return self.do_open(http.client.HTTPConnection, req)
  File "/usr/lib/python3.9/urllib/request.py", line 1349, in do_open
    raise URLError(err)
urllib.error.URLError: <urlopen error [Errno 111] Connection refused>
2024-11-21 14:19:14,450 [INFO] Freezing in a spot
2024-11-21 14:19:14,452 [INFO] Connection attempt 54, max_reconnection_attempts 180
2024-11-21 14:19:15,581 [ERROR] ConnectionWatchdog - Network is unreachable: 
Traceback (most recent call last):
  File "/usr/lib/python3.9/urllib/request.py", line 1346, in do_open
    h.request(req.get_method(), req.selector, req.data, headers,
  File "/usr/lib/python3.9/http/client.py", line 1255, in request
    self._send_request(method, url, body, headers, encode_chunked)
  File "/usr/lib/python3.9/http/client.py", line 1301, in _send_request
    self.endheaders(body, encode_chunked=encode_chunked)
  File "/usr/lib/python3.9/http/client.py", line 1250, in endheaders
    self._send_output(message_body, encode_chunked=encode_chunked)
  File "/usr/lib/python3.9/http/client.py", line 1010, in _send_output
    self.send(msg)
  File "/usr/lib/python3.9/http/client.py", line 950, in send
    self.connect()
  File "/usr/lib/python3.9/http/client.py", line 921, in connect
    self.sock = self._create_connection(
  File "/usr/lib/python3.9/socket.py", line 843, in create_connection
    raise err
  File "/usr/lib/python3.9/socket.py", line 831, in create_connection
    sock.connect(sa)
ConnectionRefusedError: [Errno 111] Connection refused

During handling of the above exception, another exception occurred:

Traceback (most recent call last):
  File "/home/gourav/raspi-app/connection_watchdog.py", line 40, in is_internet_on
    urlopen(str('http://' + self.host_ip), timeout=5)
  File "/usr/lib/python3.9/urllib/request.py", line 214, in urlopen
    return opener.open(url, data, timeout)
  File "/usr/lib/python3.9/urllib/request.py", line 517, in open
    response = self._open(req, data)
  File "/usr/lib/python3.9/urllib/request.py", line 534, in _open
    result = self._call_chain(self.handle_open, protocol, protocol +
  File "/usr/lib/python3.9/urllib/request.py", line 494, in _call_chain
    result = func(*args)
  File "/usr/lib/python3.9/urllib/request.py", line 1375, in http_open
    return self.do_open(http.client.HTTPConnection, req)
  File "/usr/lib/python3.9/urllib/request.py", line 1349, in do_open
    raise URLError(err)
urllib.error.URLError: <urlopen error [Errno 111] Connection refused>
2024-11-21 14:19:15,584 [INFO] Freezing in a spot
2024-11-21 14:19:15,585 [INFO] Connection attempt 55, max_reconnection_attempts 180
